[2024-06-18T13:13:30.656+0000] {processor.py:161} INFO - Started process (PID=4004) to work on /opt/airflow/dags/first_python_dag.py
[2024-06-18T13:13:30.657+0000] {processor.py:830} INFO - Processing file /opt/airflow/dags/first_python_dag.py for tasks to queue
[2024-06-18T13:13:30.657+0000] {logging_mixin.py:188} INFO - [2024-06-18T13:13:30.657+0000] {dagbag.py:545} INFO - Filling up the DagBag from /opt/airflow/dags/first_python_dag.py
[2024-06-18T13:13:30.659+0000] {logging_mixin.py:188} INFO - [2024-06-18T13:13:30.658+0000] {dagbag.py:355} ERROR - Failed to import: /opt/airflow/dags/first_python_dag.py
Traceback (most recent call last):
  File "/home/airflow/.local/lib/python3.12/site-packages/airflow/models/dagbag.py", line 351, in parse
    loader.exec_module(new_module)
  File "<frozen importlib._bootstrap_external>", line 991, in exec_module
  File "<frozen importlib._bootstrap_external>", line 1129, in get_code
  File "<frozen importlib._bootstrap_external>", line 1059, in source_to_code
  File "<frozen importlib._bootstrap>", line 488, in _call_with_frames_removed
  File "/opt/airflow/dags/first_python_dag.py", line 6
    'retry_delay'
                ^
SyntaxError: ':' expected after dictionary key
[2024-06-18T13:13:30.659+0000] {processor.py:842} WARNING - No viable dags retrieved from /opt/airflow/dags/first_python_dag.py
[2024-06-18T13:13:30.672+0000] {processor.py:183} INFO - Processing /opt/airflow/dags/first_python_dag.py took 0.019 seconds
[2024-06-18T13:14:00.878+0000] {processor.py:161} INFO - Started process (PID=4020) to work on /opt/airflow/dags/first_python_dag.py
[2024-06-18T13:14:00.879+0000] {processor.py:830} INFO - Processing file /opt/airflow/dags/first_python_dag.py for tasks to queue
[2024-06-18T13:14:00.879+0000] {logging_mixin.py:188} INFO - [2024-06-18T13:14:00.879+0000] {dagbag.py:545} INFO - Filling up the DagBag from /opt/airflow/dags/first_python_dag.py
[2024-06-18T13:14:00.881+0000] {logging_mixin.py:188} INFO - [2024-06-18T13:14:00.880+0000] {dagbag.py:355} ERROR - Failed to import: /opt/airflow/dags/first_python_dag.py
Traceback (most recent call last):
  File "/home/airflow/.local/lib/python3.12/site-packages/airflow/models/dagbag.py", line 351, in parse
    loader.exec_module(new_module)
  File "<frozen importlib._bootstrap_external>", line 991, in exec_module
  File "<frozen importlib._bootstrap_external>", line 1129, in get_code
  File "<frozen importlib._bootstrap_external>", line 1059, in source_to_code
  File "<frozen importlib._bootstrap>", line 488, in _call_with_frames_removed
  File "/opt/airflow/dags/first_python_dag.py", line 6
    'retry_delay'
                ^
SyntaxError: ':' expected after dictionary key
[2024-06-18T13:14:00.881+0000] {processor.py:842} WARNING - No viable dags retrieved from /opt/airflow/dags/first_python_dag.py
[2024-06-18T13:14:00.891+0000] {processor.py:183} INFO - Processing /opt/airflow/dags/first_python_dag.py took 0.018 seconds
[2024-06-18T13:14:31.111+0000] {processor.py:161} INFO - Started process (PID=4036) to work on /opt/airflow/dags/first_python_dag.py
[2024-06-18T13:14:31.113+0000] {processor.py:830} INFO - Processing file /opt/airflow/dags/first_python_dag.py for tasks to queue
[2024-06-18T13:14:31.114+0000] {logging_mixin.py:188} INFO - [2024-06-18T13:14:31.113+0000] {dagbag.py:545} INFO - Filling up the DagBag from /opt/airflow/dags/first_python_dag.py
[2024-06-18T13:14:31.115+0000] {logging_mixin.py:188} INFO - [2024-06-18T13:14:31.114+0000] {dagbag.py:355} ERROR - Failed to import: /opt/airflow/dags/first_python_dag.py
Traceback (most recent call last):
  File "/home/airflow/.local/lib/python3.12/site-packages/airflow/models/dagbag.py", line 351, in parse
    loader.exec_module(new_module)
  File "<frozen importlib._bootstrap_external>", line 991, in exec_module
  File "<frozen importlib._bootstrap_external>", line 1129, in get_code
  File "<frozen importlib._bootstrap_external>", line 1059, in source_to_code
  File "<frozen importlib._bootstrap>", line 488, in _call_with_frames_removed
  File "/opt/airflow/dags/first_python_dag.py", line 6
    'retry_delay'
                ^
SyntaxError: ':' expected after dictionary key
[2024-06-18T13:14:31.115+0000] {processor.py:842} WARNING - No viable dags retrieved from /opt/airflow/dags/first_python_dag.py
[2024-06-18T13:14:31.126+0000] {processor.py:183} INFO - Processing /opt/airflow/dags/first_python_dag.py took 0.018 seconds
[2024-06-18T13:15:01.364+0000] {processor.py:161} INFO - Started process (PID=4052) to work on /opt/airflow/dags/first_python_dag.py
[2024-06-18T13:15:01.365+0000] {processor.py:830} INFO - Processing file /opt/airflow/dags/first_python_dag.py for tasks to queue
[2024-06-18T13:15:01.366+0000] {logging_mixin.py:188} INFO - [2024-06-18T13:15:01.365+0000] {dagbag.py:545} INFO - Filling up the DagBag from /opt/airflow/dags/first_python_dag.py
[2024-06-18T13:15:01.367+0000] {logging_mixin.py:188} INFO - [2024-06-18T13:15:01.367+0000] {dagbag.py:355} ERROR - Failed to import: /opt/airflow/dags/first_python_dag.py
Traceback (most recent call last):
  File "/home/airflow/.local/lib/python3.12/site-packages/airflow/models/dagbag.py", line 351, in parse
    loader.exec_module(new_module)
  File "<frozen importlib._bootstrap_external>", line 991, in exec_module
  File "<frozen importlib._bootstrap_external>", line 1129, in get_code
  File "<frozen importlib._bootstrap_external>", line 1059, in source_to_code
  File "<frozen importlib._bootstrap>", line 488, in _call_with_frames_removed
  File "/opt/airflow/dags/first_python_dag.py", line 6
    'retry_delay'
                ^
SyntaxError: ':' expected after dictionary key
[2024-06-18T13:15:01.368+0000] {processor.py:842} WARNING - No viable dags retrieved from /opt/airflow/dags/first_python_dag.py
[2024-06-18T13:15:01.380+0000] {processor.py:183} INFO - Processing /opt/airflow/dags/first_python_dag.py took 0.021 seconds
[2024-06-18T13:15:31.597+0000] {processor.py:161} INFO - Started process (PID=4067) to work on /opt/airflow/dags/first_python_dag.py
[2024-06-18T13:15:31.598+0000] {processor.py:830} INFO - Processing file /opt/airflow/dags/first_python_dag.py for tasks to queue
[2024-06-18T13:15:31.599+0000] {logging_mixin.py:188} INFO - [2024-06-18T13:15:31.599+0000] {dagbag.py:545} INFO - Filling up the DagBag from /opt/airflow/dags/first_python_dag.py
[2024-06-18T13:15:31.600+0000] {logging_mixin.py:188} INFO - [2024-06-18T13:15:31.600+0000] {dagbag.py:355} ERROR - Failed to import: /opt/airflow/dags/first_python_dag.py
Traceback (most recent call last):
  File "/home/airflow/.local/lib/python3.12/site-packages/airflow/models/dagbag.py", line 351, in parse
    loader.exec_module(new_module)
  File "<frozen importlib._bootstrap_external>", line 991, in exec_module
  File "<frozen importlib._bootstrap_external>", line 1129, in get_code
  File "<frozen importlib._bootstrap_external>", line 1059, in source_to_code
  File "<frozen importlib._bootstrap>", line 488, in _call_with_frames_removed
  File "/opt/airflow/dags/first_python_dag.py", line 6
    'retry_delay'
                ^
SyntaxError: ':' expected after dictionary key
[2024-06-18T13:15:31.601+0000] {processor.py:842} WARNING - No viable dags retrieved from /opt/airflow/dags/first_python_dag.py
[2024-06-18T13:15:31.613+0000] {processor.py:183} INFO - Processing /opt/airflow/dags/first_python_dag.py took 0.021 seconds
[2024-06-18T13:16:01.773+0000] {processor.py:161} INFO - Started process (PID=4083) to work on /opt/airflow/dags/first_python_dag.py
[2024-06-18T13:16:01.773+0000] {processor.py:830} INFO - Processing file /opt/airflow/dags/first_python_dag.py for tasks to queue
[2024-06-18T13:16:01.774+0000] {logging_mixin.py:188} INFO - [2024-06-18T13:16:01.774+0000] {dagbag.py:545} INFO - Filling up the DagBag from /opt/airflow/dags/first_python_dag.py
[2024-06-18T13:16:01.775+0000] {logging_mixin.py:188} INFO - [2024-06-18T13:16:01.775+0000] {dagbag.py:355} ERROR - Failed to import: /opt/airflow/dags/first_python_dag.py
Traceback (most recent call last):
  File "/home/airflow/.local/lib/python3.12/site-packages/airflow/models/dagbag.py", line 351, in parse
    loader.exec_module(new_module)
  File "<frozen importlib._bootstrap_external>", line 991, in exec_module
  File "<frozen importlib._bootstrap_external>", line 1129, in get_code
  File "<frozen importlib._bootstrap_external>", line 1059, in source_to_code
  File "<frozen importlib._bootstrap>", line 488, in _call_with_frames_removed
  File "/opt/airflow/dags/first_python_dag.py", line 6
    'retry_delay'
                ^
SyntaxError: ':' expected after dictionary key
[2024-06-18T13:16:01.776+0000] {processor.py:842} WARNING - No viable dags retrieved from /opt/airflow/dags/first_python_dag.py
[2024-06-18T13:16:01.786+0000] {processor.py:183} INFO - Processing /opt/airflow/dags/first_python_dag.py took 0.018 seconds
[2024-06-18T13:16:31.983+0000] {processor.py:161} INFO - Started process (PID=4099) to work on /opt/airflow/dags/first_python_dag.py
[2024-06-18T13:16:31.985+0000] {processor.py:830} INFO - Processing file /opt/airflow/dags/first_python_dag.py for tasks to queue
[2024-06-18T13:16:31.986+0000] {logging_mixin.py:188} INFO - [2024-06-18T13:16:31.985+0000] {dagbag.py:545} INFO - Filling up the DagBag from /opt/airflow/dags/first_python_dag.py
[2024-06-18T13:16:31.987+0000] {logging_mixin.py:188} INFO - [2024-06-18T13:16:31.987+0000] {dagbag.py:355} ERROR - Failed to import: /opt/airflow/dags/first_python_dag.py
Traceback (most recent call last):
  File "/home/airflow/.local/lib/python3.12/site-packages/airflow/models/dagbag.py", line 351, in parse
    loader.exec_module(new_module)
  File "<frozen importlib._bootstrap_external>", line 991, in exec_module
  File "<frozen importlib._bootstrap_external>", line 1129, in get_code
  File "<frozen importlib._bootstrap_external>", line 1059, in source_to_code
  File "<frozen importlib._bootstrap>", line 488, in _call_with_frames_removed
  File "/opt/airflow/dags/first_python_dag.py", line 6
    'retry_delay'
                ^
SyntaxError: ':' expected after dictionary key
[2024-06-18T13:16:31.988+0000] {processor.py:842} WARNING - No viable dags retrieved from /opt/airflow/dags/first_python_dag.py
[2024-06-18T13:16:31.999+0000] {processor.py:183} INFO - Processing /opt/airflow/dags/first_python_dag.py took 0.020 seconds
[2024-06-18T13:17:02.212+0000] {processor.py:161} INFO - Started process (PID=4115) to work on /opt/airflow/dags/first_python_dag.py
[2024-06-18T13:17:02.212+0000] {processor.py:830} INFO - Processing file /opt/airflow/dags/first_python_dag.py for tasks to queue
[2024-06-18T13:17:02.213+0000] {logging_mixin.py:188} INFO - [2024-06-18T13:17:02.213+0000] {dagbag.py:545} INFO - Filling up the DagBag from /opt/airflow/dags/first_python_dag.py
[2024-06-18T13:17:02.215+0000] {logging_mixin.py:188} INFO - [2024-06-18T13:17:02.215+0000] {dagbag.py:355} ERROR - Failed to import: /opt/airflow/dags/first_python_dag.py
Traceback (most recent call last):
  File "/home/airflow/.local/lib/python3.12/site-packages/airflow/models/dagbag.py", line 351, in parse
    loader.exec_module(new_module)
  File "<frozen importlib._bootstrap_external>", line 991, in exec_module
  File "<frozen importlib._bootstrap_external>", line 1129, in get_code
  File "<frozen importlib._bootstrap_external>", line 1059, in source_to_code
  File "<frozen importlib._bootstrap>", line 488, in _call_with_frames_removed
  File "/opt/airflow/dags/first_python_dag.py", line 6
    'retry_delay'
                ^
SyntaxError: ':' expected after dictionary key
[2024-06-18T13:17:02.216+0000] {processor.py:842} WARNING - No viable dags retrieved from /opt/airflow/dags/first_python_dag.py
[2024-06-18T13:17:02.228+0000] {processor.py:183} INFO - Processing /opt/airflow/dags/first_python_dag.py took 0.024 seconds
[2024-06-18T13:17:32.429+0000] {processor.py:161} INFO - Started process (PID=4131) to work on /opt/airflow/dags/first_python_dag.py
[2024-06-18T13:17:32.431+0000] {processor.py:830} INFO - Processing file /opt/airflow/dags/first_python_dag.py for tasks to queue
[2024-06-18T13:17:32.431+0000] {logging_mixin.py:188} INFO - [2024-06-18T13:17:32.431+0000] {dagbag.py:545} INFO - Filling up the DagBag from /opt/airflow/dags/first_python_dag.py
[2024-06-18T13:17:32.433+0000] {logging_mixin.py:188} INFO - [2024-06-18T13:17:32.432+0000] {dagbag.py:355} ERROR - Failed to import: /opt/airflow/dags/first_python_dag.py
Traceback (most recent call last):
  File "/home/airflow/.local/lib/python3.12/site-packages/airflow/models/dagbag.py", line 351, in parse
    loader.exec_module(new_module)
  File "<frozen importlib._bootstrap_external>", line 991, in exec_module
  File "<frozen importlib._bootstrap_external>", line 1129, in get_code
  File "<frozen importlib._bootstrap_external>", line 1059, in source_to_code
  File "<frozen importlib._bootstrap>", line 488, in _call_with_frames_removed
  File "/opt/airflow/dags/first_python_dag.py", line 6
    'retry_delay'
                ^
SyntaxError: ':' expected after dictionary key
[2024-06-18T13:17:32.433+0000] {processor.py:842} WARNING - No viable dags retrieved from /opt/airflow/dags/first_python_dag.py
[2024-06-18T13:17:32.445+0000] {processor.py:183} INFO - Processing /opt/airflow/dags/first_python_dag.py took 0.020 seconds
[2024-06-18T13:18:02.657+0000] {processor.py:161} INFO - Started process (PID=4147) to work on /opt/airflow/dags/first_python_dag.py
[2024-06-18T13:18:02.657+0000] {processor.py:830} INFO - Processing file /opt/airflow/dags/first_python_dag.py for tasks to queue
[2024-06-18T13:18:02.658+0000] {logging_mixin.py:188} INFO - [2024-06-18T13:18:02.658+0000] {dagbag.py:545} INFO - Filling up the DagBag from /opt/airflow/dags/first_python_dag.py
[2024-06-18T13:18:02.660+0000] {logging_mixin.py:188} INFO - [2024-06-18T13:18:02.659+0000] {dagbag.py:355} ERROR - Failed to import: /opt/airflow/dags/first_python_dag.py
Traceback (most recent call last):
  File "/home/airflow/.local/lib/python3.12/site-packages/airflow/models/dagbag.py", line 351, in parse
    loader.exec_module(new_module)
  File "<frozen importlib._bootstrap_external>", line 991, in exec_module
  File "<frozen importlib._bootstrap_external>", line 1129, in get_code
  File "<frozen importlib._bootstrap_external>", line 1059, in source_to_code
  File "<frozen importlib._bootstrap>", line 488, in _call_with_frames_removed
  File "/opt/airflow/dags/first_python_dag.py", line 6
    'retry_delay'
                ^
SyntaxError: ':' expected after dictionary key
[2024-06-18T13:18:02.660+0000] {processor.py:842} WARNING - No viable dags retrieved from /opt/airflow/dags/first_python_dag.py
[2024-06-18T13:18:02.672+0000] {processor.py:183} INFO - Processing /opt/airflow/dags/first_python_dag.py took 0.020 seconds
[2024-06-18T13:18:32.913+0000] {processor.py:161} INFO - Started process (PID=4163) to work on /opt/airflow/dags/first_python_dag.py
[2024-06-18T13:18:32.914+0000] {processor.py:830} INFO - Processing file /opt/airflow/dags/first_python_dag.py for tasks to queue
[2024-06-18T13:18:32.914+0000] {logging_mixin.py:188} INFO - [2024-06-18T13:18:32.914+0000] {dagbag.py:545} INFO - Filling up the DagBag from /opt/airflow/dags/first_python_dag.py
[2024-06-18T13:18:32.917+0000] {logging_mixin.py:188} INFO - [2024-06-18T13:18:32.916+0000] {dagbag.py:355} ERROR - Failed to import: /opt/airflow/dags/first_python_dag.py
Traceback (most recent call last):
  File "/home/airflow/.local/lib/python3.12/site-packages/airflow/models/dagbag.py", line 351, in parse
    loader.exec_module(new_module)
  File "<frozen importlib._bootstrap_external>", line 991, in exec_module
  File "<frozen importlib._bootstrap_external>", line 1129, in get_code
  File "<frozen importlib._bootstrap_external>", line 1059, in source_to_code
  File "<frozen importlib._bootstrap>", line 488, in _call_with_frames_removed
  File "/opt/airflow/dags/first_python_dag.py", line 6
    'retry_delay'
                ^
SyntaxError: ':' expected after dictionary key
[2024-06-18T13:18:32.917+0000] {processor.py:842} WARNING - No viable dags retrieved from /opt/airflow/dags/first_python_dag.py
[2024-06-18T13:18:32.931+0000] {processor.py:183} INFO - Processing /opt/airflow/dags/first_python_dag.py took 0.043 seconds
[2024-06-18T13:18:54.063+0000] {processor.py:161} INFO - Started process (PID=4173) to work on /opt/airflow/dags/first_python_dag.py
[2024-06-18T13:18:54.063+0000] {processor.py:830} INFO - Processing file /opt/airflow/dags/first_python_dag.py for tasks to queue
[2024-06-18T13:18:54.064+0000] {logging_mixin.py:188} INFO - [2024-06-18T13:18:54.064+0000] {dagbag.py:545} INFO - Filling up the DagBag from /opt/airflow/dags/first_python_dag.py
[2024-06-18T13:18:54.069+0000] {logging_mixin.py:188} INFO - [2024-06-18T13:18:54.065+0000] {dagbag.py:355} ERROR - Failed to import: /opt/airflow/dags/first_python_dag.py
Traceback (most recent call last):
  File "/home/airflow/.local/lib/python3.12/site-packages/airflow/models/dagbag.py", line 351, in parse
    loader.exec_module(new_module)
  File "<frozen importlib._bootstrap_external>", line 995, in exec_module
  File "<frozen importlib._bootstrap>", line 488, in _call_with_frames_removed
  File "/opt/airflow/dags/first_python_dag.py", line 6, in <module>
    'retry_delay': timedelta(minutes),
                   ^^^^^^^^^
NameError: name 'timedelta' is not defined
[2024-06-18T13:18:54.070+0000] {processor.py:842} WARNING - No viable dags retrieved from /opt/airflow/dags/first_python_dag.py
[2024-06-18T13:18:54.084+0000] {processor.py:183} INFO - Processing /opt/airflow/dags/first_python_dag.py took 0.027 seconds
[2024-06-18T13:18:59.108+0000] {processor.py:161} INFO - Started process (PID=4184) to work on /opt/airflow/dags/first_python_dag.py
[2024-06-18T13:18:59.109+0000] {processor.py:830} INFO - Processing file /opt/airflow/dags/first_python_dag.py for tasks to queue
[2024-06-18T13:18:59.109+0000] {logging_mixin.py:188} INFO - [2024-06-18T13:18:59.109+0000] {dagbag.py:545} INFO - Filling up the DagBag from /opt/airflow/dags/first_python_dag.py
[2024-06-18T13:18:59.114+0000] {logging_mixin.py:188} INFO - [2024-06-18T13:18:59.111+0000] {dagbag.py:355} ERROR - Failed to import: /opt/airflow/dags/first_python_dag.py
Traceback (most recent call last):
  File "/home/airflow/.local/lib/python3.12/site-packages/airflow/models/dagbag.py", line 351, in parse
    loader.exec_module(new_module)
  File "<frozen importlib._bootstrap_external>", line 995, in exec_module
  File "<frozen importlib._bootstrap>", line 488, in _call_with_frames_removed
  File "/opt/airflow/dags/first_python_dag.py", line 6, in <module>
    'retry_delay': timedelta(minutes=5),
                   ^^^^^^^^^
NameError: name 'timedelta' is not defined
[2024-06-18T13:18:59.116+0000] {processor.py:842} WARNING - No viable dags retrieved from /opt/airflow/dags/first_python_dag.py
[2024-06-18T13:18:59.157+0000] {processor.py:183} INFO - Processing /opt/airflow/dags/first_python_dag.py took 0.056 seconds
[2024-06-18T13:19:08.238+0000] {processor.py:161} INFO - Started process (PID=4194) to work on /opt/airflow/dags/first_python_dag.py
[2024-06-18T13:19:08.239+0000] {processor.py:830} INFO - Processing file /opt/airflow/dags/first_python_dag.py for tasks to queue
[2024-06-18T13:19:08.239+0000] {logging_mixin.py:188} INFO - [2024-06-18T13:19:08.239+0000] {dagbag.py:545} INFO - Filling up the DagBag from /opt/airflow/dags/first_python_dag.py
[2024-06-18T13:19:08.269+0000] {logging_mixin.py:188} INFO - [2024-06-18T13:19:08.242+0000] {dagbag.py:355} ERROR - Failed to import: /opt/airflow/dags/first_python_dag.py
Traceback (most recent call last):
  File "/home/airflow/.local/lib/python3.12/site-packages/airflow/models/dagbag.py", line 351, in parse
    loader.exec_module(new_module)
  File "<frozen importlib._bootstrap_external>", line 995, in exec_module
  File "<frozen importlib._bootstrap>", line 488, in _call_with_frames_removed
  File "/opt/airflow/dags/first_python_dag.py", line 7, in <module>
    'retry_delay': timedelta(minutes=5),
                   ^^^^^^^^^
NameError: name 'timedelta' is not defined
[2024-06-18T13:19:08.272+0000] {processor.py:842} WARNING - No viable dags retrieved from /opt/airflow/dags/first_python_dag.py
[2024-06-18T13:19:08.310+0000] {processor.py:183} INFO - Processing /opt/airflow/dags/first_python_dag.py took 0.076 seconds
[2024-06-18T13:19:16.311+0000] {processor.py:161} INFO - Started process (PID=4199) to work on /opt/airflow/dags/first_python_dag.py
[2024-06-18T13:19:16.311+0000] {processor.py:830} INFO - Processing file /opt/airflow/dags/first_python_dag.py for tasks to queue
[2024-06-18T13:19:16.312+0000] {logging_mixin.py:188} INFO - [2024-06-18T13:19:16.311+0000] {dagbag.py:545} INFO - Filling up the DagBag from /opt/airflow/dags/first_python_dag.py
[2024-06-18T13:19:16.313+0000] {processor.py:842} WARNING - No viable dags retrieved from /opt/airflow/dags/first_python_dag.py
[2024-06-18T13:19:16.321+0000] {processor.py:183} INFO - Processing /opt/airflow/dags/first_python_dag.py took 0.015 seconds
[2024-06-18T13:19:46.544+0000] {processor.py:161} INFO - Started process (PID=4215) to work on /opt/airflow/dags/first_python_dag.py
[2024-06-18T13:19:46.546+0000] {processor.py:830} INFO - Processing file /opt/airflow/dags/first_python_dag.py for tasks to queue
[2024-06-18T13:19:46.547+0000] {logging_mixin.py:188} INFO - [2024-06-18T13:19:46.546+0000] {dagbag.py:545} INFO - Filling up the DagBag from /opt/airflow/dags/first_python_dag.py
[2024-06-18T13:19:46.548+0000] {processor.py:842} WARNING - No viable dags retrieved from /opt/airflow/dags/first_python_dag.py
[2024-06-18T13:19:46.556+0000] {processor.py:183} INFO - Processing /opt/airflow/dags/first_python_dag.py took 0.017 seconds
[2024-06-18T13:19:49.573+0000] {processor.py:161} INFO - Started process (PID=4220) to work on /opt/airflow/dags/first_python_dag.py
[2024-06-18T13:19:49.573+0000] {processor.py:830} INFO - Processing file /opt/airflow/dags/first_python_dag.py for tasks to queue
[2024-06-18T13:19:49.574+0000] {logging_mixin.py:188} INFO - [2024-06-18T13:19:49.573+0000] {dagbag.py:545} INFO - Filling up the DagBag from /opt/airflow/dags/first_python_dag.py
[2024-06-18T13:19:49.575+0000] {logging_mixin.py:188} INFO - [2024-06-18T13:19:49.575+0000] {dagbag.py:355} ERROR - Failed to import: /opt/airflow/dags/first_python_dag.py
Traceback (most recent call last):
  File "/home/airflow/.local/lib/python3.12/site-packages/airflow/models/dagbag.py", line 351, in parse
    loader.exec_module(new_module)
  File "<frozen importlib._bootstrap_external>", line 991, in exec_module
  File "<frozen importlib._bootstrap_external>", line 1129, in get_code
  File "<frozen importlib._bootstrap_external>", line 1059, in source_to_code
  File "<frozen importlib._bootstrap>", line 488, in _call_with_frames_removed
  File "/opt/airflow/dags/first_python_dag.py", line 12
    )
     ^
SyntaxError: expected ':'
[2024-06-18T13:19:49.576+0000] {processor.py:842} WARNING - No viable dags retrieved from /opt/airflow/dags/first_python_dag.py
[2024-06-18T13:19:49.587+0000] {processor.py:183} INFO - Processing /opt/airflow/dags/first_python_dag.py took 0.019 seconds
[2024-06-18T13:20:19.802+0000] {processor.py:161} INFO - Started process (PID=4236) to work on /opt/airflow/dags/first_python_dag.py
[2024-06-18T13:20:19.804+0000] {processor.py:830} INFO - Processing file /opt/airflow/dags/first_python_dag.py for tasks to queue
[2024-06-18T13:20:19.805+0000] {logging_mixin.py:188} INFO - [2024-06-18T13:20:19.805+0000] {dagbag.py:545} INFO - Filling up the DagBag from /opt/airflow/dags/first_python_dag.py
[2024-06-18T13:20:19.806+0000] {logging_mixin.py:188} INFO - [2024-06-18T13:20:19.806+0000] {dagbag.py:355} ERROR - Failed to import: /opt/airflow/dags/first_python_dag.py
Traceback (most recent call last):
  File "/home/airflow/.local/lib/python3.12/site-packages/airflow/models/dagbag.py", line 351, in parse
    loader.exec_module(new_module)
  File "<frozen importlib._bootstrap_external>", line 991, in exec_module
  File "<frozen importlib._bootstrap_external>", line 1129, in get_code
  File "<frozen importlib._bootstrap_external>", line 1059, in source_to_code
  File "<frozen importlib._bootstrap>", line 488, in _call_with_frames_removed
  File "/opt/airflow/dags/first_python_dag.py", line 12
    )
     ^
SyntaxError: expected ':'
[2024-06-18T13:20:19.807+0000] {processor.py:842} WARNING - No viable dags retrieved from /opt/airflow/dags/first_python_dag.py
[2024-06-18T13:20:19.820+0000] {processor.py:183} INFO - Processing /opt/airflow/dags/first_python_dag.py took 0.024 seconds
[2024-06-18T13:20:50.047+0000] {processor.py:161} INFO - Started process (PID=4252) to work on /opt/airflow/dags/first_python_dag.py
[2024-06-18T13:20:50.047+0000] {processor.py:830} INFO - Processing file /opt/airflow/dags/first_python_dag.py for tasks to queue
[2024-06-18T13:20:50.048+0000] {logging_mixin.py:188} INFO - [2024-06-18T13:20:50.048+0000] {dagbag.py:545} INFO - Filling up the DagBag from /opt/airflow/dags/first_python_dag.py
[2024-06-18T13:20:50.051+0000] {logging_mixin.py:188} INFO - [2024-06-18T13:20:50.050+0000] {dagbag.py:355} ERROR - Failed to import: /opt/airflow/dags/first_python_dag.py
Traceback (most recent call last):
  File "/home/airflow/.local/lib/python3.12/site-packages/airflow/models/dagbag.py", line 351, in parse
    loader.exec_module(new_module)
  File "<frozen importlib._bootstrap_external>", line 991, in exec_module
  File "<frozen importlib._bootstrap_external>", line 1129, in get_code
  File "<frozen importlib._bootstrap_external>", line 1059, in source_to_code
  File "<frozen importlib._bootstrap>", line 488, in _call_with_frames_removed
  File "/opt/airflow/dags/first_python_dag.py", line 12
    )
     ^
SyntaxError: expected ':'
[2024-06-18T13:20:50.051+0000] {processor.py:842} WARNING - No viable dags retrieved from /opt/airflow/dags/first_python_dag.py
[2024-06-18T13:20:50.065+0000] {processor.py:183} INFO - Processing /opt/airflow/dags/first_python_dag.py took 0.023 seconds
[2024-06-18T13:21:20.245+0000] {processor.py:161} INFO - Started process (PID=4268) to work on /opt/airflow/dags/first_python_dag.py
[2024-06-18T13:21:20.247+0000] {processor.py:830} INFO - Processing file /opt/airflow/dags/first_python_dag.py for tasks to queue
[2024-06-18T13:21:20.248+0000] {logging_mixin.py:188} INFO - [2024-06-18T13:21:20.247+0000] {dagbag.py:545} INFO - Filling up the DagBag from /opt/airflow/dags/first_python_dag.py
[2024-06-18T13:21:20.249+0000] {logging_mixin.py:188} INFO - [2024-06-18T13:21:20.249+0000] {dagbag.py:355} ERROR - Failed to import: /opt/airflow/dags/first_python_dag.py
Traceback (most recent call last):
  File "/home/airflow/.local/lib/python3.12/site-packages/airflow/models/dagbag.py", line 351, in parse
    loader.exec_module(new_module)
  File "<frozen importlib._bootstrap_external>", line 991, in exec_module
  File "<frozen importlib._bootstrap_external>", line 1129, in get_code
  File "<frozen importlib._bootstrap_external>", line 1059, in source_to_code
  File "<frozen importlib._bootstrap>", line 488, in _call_with_frames_removed
  File "/opt/airflow/dags/first_python_dag.py", line 12
    )
     ^
SyntaxError: expected ':'
[2024-06-18T13:21:20.250+0000] {processor.py:842} WARNING - No viable dags retrieved from /opt/airflow/dags/first_python_dag.py
[2024-06-18T13:21:20.261+0000] {processor.py:183} INFO - Processing /opt/airflow/dags/first_python_dag.py took 0.022 seconds
[2024-06-18T13:21:50.453+0000] {processor.py:161} INFO - Started process (PID=4284) to work on /opt/airflow/dags/first_python_dag.py
[2024-06-18T13:21:50.454+0000] {processor.py:830} INFO - Processing file /opt/airflow/dags/first_python_dag.py for tasks to queue
[2024-06-18T13:21:50.455+0000] {logging_mixin.py:188} INFO - [2024-06-18T13:21:50.454+0000] {dagbag.py:545} INFO - Filling up the DagBag from /opt/airflow/dags/first_python_dag.py
[2024-06-18T13:21:50.456+0000] {logging_mixin.py:188} INFO - [2024-06-18T13:21:50.456+0000] {dagbag.py:355} ERROR - Failed to import: /opt/airflow/dags/first_python_dag.py
Traceback (most recent call last):
  File "/home/airflow/.local/lib/python3.12/site-packages/airflow/models/dagbag.py", line 351, in parse
    loader.exec_module(new_module)
  File "<frozen importlib._bootstrap_external>", line 991, in exec_module
  File "<frozen importlib._bootstrap_external>", line 1129, in get_code
  File "<frozen importlib._bootstrap_external>", line 1059, in source_to_code
  File "<frozen importlib._bootstrap>", line 488, in _call_with_frames_removed
  File "/opt/airflow/dags/first_python_dag.py", line 12
    )
     ^
SyntaxError: expected ':'
[2024-06-18T13:21:50.457+0000] {processor.py:842} WARNING - No viable dags retrieved from /opt/airflow/dags/first_python_dag.py
[2024-06-18T13:21:50.468+0000] {processor.py:183} INFO - Processing /opt/airflow/dags/first_python_dag.py took 0.020 seconds
[2024-06-18T13:22:20.656+0000] {processor.py:161} INFO - Started process (PID=4300) to work on /opt/airflow/dags/first_python_dag.py
[2024-06-18T13:22:20.658+0000] {processor.py:830} INFO - Processing file /opt/airflow/dags/first_python_dag.py for tasks to queue
[2024-06-18T13:22:20.658+0000] {logging_mixin.py:188} INFO - [2024-06-18T13:22:20.658+0000] {dagbag.py:545} INFO - Filling up the DagBag from /opt/airflow/dags/first_python_dag.py
[2024-06-18T13:22:20.660+0000] {logging_mixin.py:188} INFO - [2024-06-18T13:22:20.659+0000] {dagbag.py:355} ERROR - Failed to import: /opt/airflow/dags/first_python_dag.py
Traceback (most recent call last):
  File "/home/airflow/.local/lib/python3.12/site-packages/airflow/models/dagbag.py", line 351, in parse
    loader.exec_module(new_module)
  File "<frozen importlib._bootstrap_external>", line 991, in exec_module
  File "<frozen importlib._bootstrap_external>", line 1129, in get_code
  File "<frozen importlib._bootstrap_external>", line 1059, in source_to_code
  File "<frozen importlib._bootstrap>", line 488, in _call_with_frames_removed
  File "/opt/airflow/dags/first_python_dag.py", line 12
    )
     ^
SyntaxError: expected ':'
[2024-06-18T13:22:20.660+0000] {processor.py:842} WARNING - No viable dags retrieved from /opt/airflow/dags/first_python_dag.py
[2024-06-18T13:22:20.671+0000] {processor.py:183} INFO - Processing /opt/airflow/dags/first_python_dag.py took 0.019 seconds
[2024-06-18T13:22:50.857+0000] {processor.py:161} INFO - Started process (PID=4316) to work on /opt/airflow/dags/first_python_dag.py
[2024-06-18T13:22:50.857+0000] {processor.py:830} INFO - Processing file /opt/airflow/dags/first_python_dag.py for tasks to queue
[2024-06-18T13:22:50.858+0000] {logging_mixin.py:188} INFO - [2024-06-18T13:22:50.857+0000] {dagbag.py:545} INFO - Filling up the DagBag from /opt/airflow/dags/first_python_dag.py
[2024-06-18T13:22:50.859+0000] {logging_mixin.py:188} INFO - [2024-06-18T13:22:50.859+0000] {dagbag.py:355} ERROR - Failed to import: /opt/airflow/dags/first_python_dag.py
Traceback (most recent call last):
  File "/home/airflow/.local/lib/python3.12/site-packages/airflow/models/dagbag.py", line 351, in parse
    loader.exec_module(new_module)
  File "<frozen importlib._bootstrap_external>", line 991, in exec_module
  File "<frozen importlib._bootstrap_external>", line 1129, in get_code
  File "<frozen importlib._bootstrap_external>", line 1059, in source_to_code
  File "<frozen importlib._bootstrap>", line 488, in _call_with_frames_removed
  File "/opt/airflow/dags/first_python_dag.py", line 12
    )
     ^
SyntaxError: expected ':'
[2024-06-18T13:22:50.860+0000] {processor.py:842} WARNING - No viable dags retrieved from /opt/airflow/dags/first_python_dag.py
[2024-06-18T13:22:50.870+0000] {processor.py:183} INFO - Processing /opt/airflow/dags/first_python_dag.py took 0.019 seconds
[2024-06-18T13:22:54.918+0000] {processor.py:161} INFO - Started process (PID=4321) to work on /opt/airflow/dags/first_python_dag.py
[2024-06-18T13:22:54.918+0000] {processor.py:830} INFO - Processing file /opt/airflow/dags/first_python_dag.py for tasks to queue
[2024-06-18T13:22:54.919+0000] {logging_mixin.py:188} INFO - [2024-06-18T13:22:54.918+0000] {dagbag.py:545} INFO - Filling up the DagBag from /opt/airflow/dags/first_python_dag.py
[2024-06-18T13:22:54.920+0000] {logging_mixin.py:188} INFO - [2024-06-18T13:22:54.920+0000] {dagbag.py:355} ERROR - Failed to import: /opt/airflow/dags/first_python_dag.py
Traceback (most recent call last):
  File "/home/airflow/.local/lib/python3.12/site-packages/airflow/models/dagbag.py", line 351, in parse
    loader.exec_module(new_module)
  File "<frozen importlib._bootstrap_external>", line 991, in exec_module
  File "<frozen importlib._bootstrap_external>", line 1129, in get_code
  File "<frozen importlib._bootstrap_external>", line 1059, in source_to_code
  File "<frozen importlib._bootstrap>", line 488, in _call_with_frames_removed
  File "/opt/airflow/dags/first_python_dag.py", line 13
    )
     ^
SyntaxError: expected ':'
[2024-06-18T13:22:54.920+0000] {processor.py:842} WARNING - No viable dags retrieved from /opt/airflow/dags/first_python_dag.py
[2024-06-18T13:22:54.931+0000] {processor.py:183} INFO - Processing /opt/airflow/dags/first_python_dag.py took 0.029 seconds
[2024-06-18T13:23:25.140+0000] {processor.py:161} INFO - Started process (PID=4337) to work on /opt/airflow/dags/first_python_dag.py
[2024-06-18T13:23:25.142+0000] {processor.py:830} INFO - Processing file /opt/airflow/dags/first_python_dag.py for tasks to queue
[2024-06-18T13:23:25.143+0000] {logging_mixin.py:188} INFO - [2024-06-18T13:23:25.142+0000] {dagbag.py:545} INFO - Filling up the DagBag from /opt/airflow/dags/first_python_dag.py
[2024-06-18T13:23:25.144+0000] {logging_mixin.py:188} INFO - [2024-06-18T13:23:25.144+0000] {dagbag.py:355} ERROR - Failed to import: /opt/airflow/dags/first_python_dag.py
Traceback (most recent call last):
  File "/home/airflow/.local/lib/python3.12/site-packages/airflow/models/dagbag.py", line 351, in parse
    loader.exec_module(new_module)
  File "<frozen importlib._bootstrap_external>", line 991, in exec_module
  File "<frozen importlib._bootstrap_external>", line 1129, in get_code
  File "<frozen importlib._bootstrap_external>", line 1059, in source_to_code
  File "<frozen importlib._bootstrap>", line 488, in _call_with_frames_removed
  File "/opt/airflow/dags/first_python_dag.py", line 13
    )
     ^
SyntaxError: expected ':'
[2024-06-18T13:23:25.145+0000] {processor.py:842} WARNING - No viable dags retrieved from /opt/airflow/dags/first_python_dag.py
[2024-06-18T13:23:25.154+0000] {processor.py:183} INFO - Processing /opt/airflow/dags/first_python_dag.py took 0.020 seconds
[2024-06-18T13:23:36.233+0000] {processor.py:161} INFO - Started process (PID=4348) to work on /opt/airflow/dags/first_python_dag.py
[2024-06-18T13:23:36.234+0000] {processor.py:830} INFO - Processing file /opt/airflow/dags/first_python_dag.py for tasks to queue
[2024-06-18T13:23:36.234+0000] {logging_mixin.py:188} INFO - [2024-06-18T13:23:36.234+0000] {dagbag.py:545} INFO - Filling up the DagBag from /opt/airflow/dags/first_python_dag.py
[2024-06-18T13:23:36.236+0000] {logging_mixin.py:188} INFO - [2024-06-18T13:23:36.235+0000] {dagbag.py:355} ERROR - Failed to import: /opt/airflow/dags/first_python_dag.py
Traceback (most recent call last):
  File "/home/airflow/.local/lib/python3.12/site-packages/airflow/models/dagbag.py", line 351, in parse
    loader.exec_module(new_module)
  File "<frozen importlib._bootstrap_external>", line 991, in exec_module
  File "<frozen importlib._bootstrap_external>", line 1129, in get_code
  File "<frozen importlib._bootstrap_external>", line 1059, in source_to_code
  File "<frozen importlib._bootstrap>", line 488, in _call_with_frames_removed
  File "/opt/airflow/dags/first_python_dag.py", line 14
    )
     ^
SyntaxError: expected ':'
[2024-06-18T13:23:36.236+0000] {processor.py:842} WARNING - No viable dags retrieved from /opt/airflow/dags/first_python_dag.py
[2024-06-18T13:23:36.251+0000] {processor.py:183} INFO - Processing /opt/airflow/dags/first_python_dag.py took 0.022 seconds
[2024-06-18T13:24:04.458+0000] {processor.py:161} INFO - Started process (PID=4364) to work on /opt/airflow/dags/first_python_dag.py
[2024-06-18T13:24:04.460+0000] {processor.py:830} INFO - Processing file /opt/airflow/dags/first_python_dag.py for tasks to queue
[2024-06-18T13:24:04.461+0000] {logging_mixin.py:188} INFO - [2024-06-18T13:24:04.461+0000] {dagbag.py:545} INFO - Filling up the DagBag from /opt/airflow/dags/first_python_dag.py
[2024-06-18T13:24:04.463+0000] {logging_mixin.py:188} INFO - [2024-06-18T13:24:04.462+0000] {dagbag.py:355} ERROR - Failed to import: /opt/airflow/dags/first_python_dag.py
Traceback (most recent call last):
  File "/home/airflow/.local/lib/python3.12/site-packages/airflow/models/dagbag.py", line 351, in parse
    loader.exec_module(new_module)
  File "<frozen importlib._bootstrap_external>", line 991, in exec_module
  File "<frozen importlib._bootstrap_external>", line 1129, in get_code
  File "<frozen importlib._bootstrap_external>", line 1059, in source_to_code
  File "<frozen importlib._bootstrap>", line 488, in _call_with_frames_removed
  File "/opt/airflow/dags/first_python_dag.py", line 15
    )
     ^
SyntaxError: expected ':'
[2024-06-18T13:24:04.463+0000] {processor.py:842} WARNING - No viable dags retrieved from /opt/airflow/dags/first_python_dag.py
[2024-06-18T13:24:04.477+0000] {processor.py:183} INFO - Processing /opt/airflow/dags/first_python_dag.py took 0.022 seconds
[2024-06-18T13:24:34.672+0000] {processor.py:161} INFO - Started process (PID=4380) to work on /opt/airflow/dags/first_python_dag.py
[2024-06-18T13:24:34.672+0000] {processor.py:830} INFO - Processing file /opt/airflow/dags/first_python_dag.py for tasks to queue
[2024-06-18T13:24:34.673+0000] {logging_mixin.py:188} INFO - [2024-06-18T13:24:34.672+0000] {dagbag.py:545} INFO - Filling up the DagBag from /opt/airflow/dags/first_python_dag.py
[2024-06-18T13:24:34.674+0000] {logging_mixin.py:188} INFO - [2024-06-18T13:24:34.674+0000] {dagbag.py:355} ERROR - Failed to import: /opt/airflow/dags/first_python_dag.py
Traceback (most recent call last):
  File "/home/airflow/.local/lib/python3.12/site-packages/airflow/models/dagbag.py", line 351, in parse
    loader.exec_module(new_module)
  File "<frozen importlib._bootstrap_external>", line 991, in exec_module
  File "<frozen importlib._bootstrap_external>", line 1129, in get_code
  File "<frozen importlib._bootstrap_external>", line 1059, in source_to_code
  File "<frozen importlib._bootstrap>", line 488, in _call_with_frames_removed
  File "/opt/airflow/dags/first_python_dag.py", line 15
    )
     ^
SyntaxError: expected ':'
[2024-06-18T13:24:34.675+0000] {processor.py:842} WARNING - No viable dags retrieved from /opt/airflow/dags/first_python_dag.py
[2024-06-18T13:24:34.686+0000] {processor.py:183} INFO - Processing /opt/airflow/dags/first_python_dag.py took 0.018 seconds
[2024-06-18T13:25:04.870+0000] {processor.py:161} INFO - Started process (PID=4396) to work on /opt/airflow/dags/first_python_dag.py
[2024-06-18T13:25:04.872+0000] {processor.py:830} INFO - Processing file /opt/airflow/dags/first_python_dag.py for tasks to queue
[2024-06-18T13:25:04.872+0000] {logging_mixin.py:188} INFO - [2024-06-18T13:25:04.872+0000] {dagbag.py:545} INFO - Filling up the DagBag from /opt/airflow/dags/first_python_dag.py
[2024-06-18T13:25:04.886+0000] {logging_mixin.py:188} INFO - [2024-06-18T13:25:04.881+0000] {dagbag.py:355} ERROR - Failed to import: /opt/airflow/dags/first_python_dag.py
Traceback (most recent call last):
  File "/home/airflow/.local/lib/python3.12/site-packages/airflow/models/dagbag.py", line 351, in parse
    loader.exec_module(new_module)
  File "<frozen importlib._bootstrap_external>", line 991, in exec_module
  File "<frozen importlib._bootstrap_external>", line 1129, in get_code
  File "<frozen importlib._bootstrap_external>", line 1059, in source_to_code
  File "<frozen importlib._bootstrap>", line 488, in _call_with_frames_removed
  File "/opt/airflow/dags/first_python_dag.py", line 15
    )
     ^
SyntaxError: expected ':'
[2024-06-18T13:25:04.887+0000] {processor.py:842} WARNING - No viable dags retrieved from /opt/airflow/dags/first_python_dag.py
[2024-06-18T13:25:04.916+0000] {processor.py:183} INFO - Processing /opt/airflow/dags/first_python_dag.py took 0.049 seconds
[2024-06-18T13:25:35.057+0000] {processor.py:161} INFO - Started process (PID=4412) to work on /opt/airflow/dags/first_python_dag.py
[2024-06-18T13:25:35.058+0000] {processor.py:830} INFO - Processing file /opt/airflow/dags/first_python_dag.py for tasks to queue
[2024-06-18T13:25:35.058+0000] {logging_mixin.py:188} INFO - [2024-06-18T13:25:35.058+0000] {dagbag.py:545} INFO - Filling up the DagBag from /opt/airflow/dags/first_python_dag.py
[2024-06-18T13:25:35.060+0000] {logging_mixin.py:188} INFO - [2024-06-18T13:25:35.059+0000] {dagbag.py:355} ERROR - Failed to import: /opt/airflow/dags/first_python_dag.py
Traceback (most recent call last):
  File "/home/airflow/.local/lib/python3.12/site-packages/airflow/models/dagbag.py", line 351, in parse
    loader.exec_module(new_module)
  File "<frozen importlib._bootstrap_external>", line 991, in exec_module
  File "<frozen importlib._bootstrap_external>", line 1129, in get_code
  File "<frozen importlib._bootstrap_external>", line 1059, in source_to_code
  File "<frozen importlib._bootstrap>", line 488, in _call_with_frames_removed
  File "/opt/airflow/dags/first_python_dag.py", line 15
    )
     ^
SyntaxError: expected ':'
[2024-06-18T13:25:35.060+0000] {processor.py:842} WARNING - No viable dags retrieved from /opt/airflow/dags/first_python_dag.py
[2024-06-18T13:25:35.071+0000] {processor.py:183} INFO - Processing /opt/airflow/dags/first_python_dag.py took 0.017 seconds
[2024-06-18T13:26:05.302+0000] {processor.py:161} INFO - Started process (PID=4428) to work on /opt/airflow/dags/first_python_dag.py
[2024-06-18T13:26:05.304+0000] {processor.py:830} INFO - Processing file /opt/airflow/dags/first_python_dag.py for tasks to queue
[2024-06-18T13:26:05.304+0000] {logging_mixin.py:188} INFO - [2024-06-18T13:26:05.304+0000] {dagbag.py:545} INFO - Filling up the DagBag from /opt/airflow/dags/first_python_dag.py
[2024-06-18T13:26:05.305+0000] {logging_mixin.py:188} INFO - [2024-06-18T13:26:05.305+0000] {dagbag.py:355} ERROR - Failed to import: /opt/airflow/dags/first_python_dag.py
Traceback (most recent call last):
  File "/home/airflow/.local/lib/python3.12/site-packages/airflow/models/dagbag.py", line 351, in parse
    loader.exec_module(new_module)
  File "<frozen importlib._bootstrap_external>", line 991, in exec_module
  File "<frozen importlib._bootstrap_external>", line 1129, in get_code
  File "<frozen importlib._bootstrap_external>", line 1059, in source_to_code
  File "<frozen importlib._bootstrap>", line 488, in _call_with_frames_removed
  File "/opt/airflow/dags/first_python_dag.py", line 15
    )
     ^
SyntaxError: expected ':'
[2024-06-18T13:26:05.306+0000] {processor.py:842} WARNING - No viable dags retrieved from /opt/airflow/dags/first_python_dag.py
[2024-06-18T13:26:05.316+0000] {processor.py:183} INFO - Processing /opt/airflow/dags/first_python_dag.py took 0.019 seconds
[2024-06-18T13:26:35.524+0000] {processor.py:161} INFO - Started process (PID=4443) to work on /opt/airflow/dags/first_python_dag.py
[2024-06-18T13:26:35.526+0000] {processor.py:830} INFO - Processing file /opt/airflow/dags/first_python_dag.py for tasks to queue
[2024-06-18T13:26:35.526+0000] {logging_mixin.py:188} INFO - [2024-06-18T13:26:35.526+0000] {dagbag.py:545} INFO - Filling up the DagBag from /opt/airflow/dags/first_python_dag.py
[2024-06-18T13:26:35.528+0000] {logging_mixin.py:188} INFO - [2024-06-18T13:26:35.527+0000] {dagbag.py:355} ERROR - Failed to import: /opt/airflow/dags/first_python_dag.py
Traceback (most recent call last):
  File "/home/airflow/.local/lib/python3.12/site-packages/airflow/models/dagbag.py", line 351, in parse
    loader.exec_module(new_module)
  File "<frozen importlib._bootstrap_external>", line 991, in exec_module
  File "<frozen importlib._bootstrap_external>", line 1129, in get_code
  File "<frozen importlib._bootstrap_external>", line 1059, in source_to_code
  File "<frozen importlib._bootstrap>", line 488, in _call_with_frames_removed
  File "/opt/airflow/dags/first_python_dag.py", line 15
    )
     ^
SyntaxError: expected ':'
[2024-06-18T13:26:35.528+0000] {processor.py:842} WARNING - No viable dags retrieved from /opt/airflow/dags/first_python_dag.py
[2024-06-18T13:26:35.540+0000] {processor.py:183} INFO - Processing /opt/airflow/dags/first_python_dag.py took 0.019 seconds
[2024-06-18T13:27:05.745+0000] {processor.py:161} INFO - Started process (PID=4459) to work on /opt/airflow/dags/first_python_dag.py
[2024-06-18T13:27:05.746+0000] {processor.py:830} INFO - Processing file /opt/airflow/dags/first_python_dag.py for tasks to queue
[2024-06-18T13:27:05.747+0000] {logging_mixin.py:188} INFO - [2024-06-18T13:27:05.747+0000] {dagbag.py:545} INFO - Filling up the DagBag from /opt/airflow/dags/first_python_dag.py
[2024-06-18T13:27:05.749+0000] {logging_mixin.py:188} INFO - [2024-06-18T13:27:05.748+0000] {dagbag.py:355} ERROR - Failed to import: /opt/airflow/dags/first_python_dag.py
Traceback (most recent call last):
  File "/home/airflow/.local/lib/python3.12/site-packages/airflow/models/dagbag.py", line 351, in parse
    loader.exec_module(new_module)
  File "<frozen importlib._bootstrap_external>", line 991, in exec_module
  File "<frozen importlib._bootstrap_external>", line 1129, in get_code
  File "<frozen importlib._bootstrap_external>", line 1059, in source_to_code
  File "<frozen importlib._bootstrap>", line 488, in _call_with_frames_removed
  File "/opt/airflow/dags/first_python_dag.py", line 15
    )
     ^
SyntaxError: expected ':'
[2024-06-18T13:27:05.749+0000] {processor.py:842} WARNING - No viable dags retrieved from /opt/airflow/dags/first_python_dag.py
[2024-06-18T13:27:05.760+0000] {processor.py:183} INFO - Processing /opt/airflow/dags/first_python_dag.py took 0.019 seconds
[2024-06-18T13:27:35.942+0000] {processor.py:161} INFO - Started process (PID=4475) to work on /opt/airflow/dags/first_python_dag.py
[2024-06-18T13:27:35.944+0000] {processor.py:830} INFO - Processing file /opt/airflow/dags/first_python_dag.py for tasks to queue
[2024-06-18T13:27:35.944+0000] {logging_mixin.py:188} INFO - [2024-06-18T13:27:35.944+0000] {dagbag.py:545} INFO - Filling up the DagBag from /opt/airflow/dags/first_python_dag.py
[2024-06-18T13:27:35.946+0000] {logging_mixin.py:188} INFO - [2024-06-18T13:27:35.945+0000] {dagbag.py:355} ERROR - Failed to import: /opt/airflow/dags/first_python_dag.py
Traceback (most recent call last):
  File "/home/airflow/.local/lib/python3.12/site-packages/airflow/models/dagbag.py", line 351, in parse
    loader.exec_module(new_module)
  File "<frozen importlib._bootstrap_external>", line 991, in exec_module
  File "<frozen importlib._bootstrap_external>", line 1129, in get_code
  File "<frozen importlib._bootstrap_external>", line 1059, in source_to_code
  File "<frozen importlib._bootstrap>", line 488, in _call_with_frames_removed
  File "/opt/airflow/dags/first_python_dag.py", line 15
    )
     ^
SyntaxError: expected ':'
[2024-06-18T13:27:35.946+0000] {processor.py:842} WARNING - No viable dags retrieved from /opt/airflow/dags/first_python_dag.py
[2024-06-18T13:27:35.956+0000] {processor.py:183} INFO - Processing /opt/airflow/dags/first_python_dag.py took 0.017 seconds
[2024-06-18T13:28:06.156+0000] {processor.py:161} INFO - Started process (PID=4491) to work on /opt/airflow/dags/first_python_dag.py
[2024-06-18T13:28:06.156+0000] {processor.py:830} INFO - Processing file /opt/airflow/dags/first_python_dag.py for tasks to queue
[2024-06-18T13:28:06.157+0000] {logging_mixin.py:188} INFO - [2024-06-18T13:28:06.157+0000] {dagbag.py:545} INFO - Filling up the DagBag from /opt/airflow/dags/first_python_dag.py
[2024-06-18T13:28:06.171+0000] {logging_mixin.py:188} INFO - [2024-06-18T13:28:06.160+0000] {dagbag.py:355} ERROR - Failed to import: /opt/airflow/dags/first_python_dag.py
Traceback (most recent call last):
  File "/home/airflow/.local/lib/python3.12/site-packages/airflow/models/dagbag.py", line 351, in parse
    loader.exec_module(new_module)
  File "<frozen importlib._bootstrap_external>", line 991, in exec_module
  File "<frozen importlib._bootstrap_external>", line 1129, in get_code
  File "<frozen importlib._bootstrap_external>", line 1059, in source_to_code
  File "<frozen importlib._bootstrap>", line 488, in _call_with_frames_removed
  File "/opt/airflow/dags/first_python_dag.py", line 15
    )
     ^
SyntaxError: expected ':'
[2024-06-18T13:28:06.173+0000] {processor.py:842} WARNING - No viable dags retrieved from /opt/airflow/dags/first_python_dag.py
[2024-06-18T13:28:06.192+0000] {processor.py:183} INFO - Processing /opt/airflow/dags/first_python_dag.py took 0.039 seconds
[2024-06-18T13:28:36.420+0000] {processor.py:161} INFO - Started process (PID=4507) to work on /opt/airflow/dags/first_python_dag.py
[2024-06-18T13:28:36.422+0000] {processor.py:830} INFO - Processing file /opt/airflow/dags/first_python_dag.py for tasks to queue
[2024-06-18T13:28:36.423+0000] {logging_mixin.py:188} INFO - [2024-06-18T13:28:36.423+0000] {dagbag.py:545} INFO - Filling up the DagBag from /opt/airflow/dags/first_python_dag.py
[2024-06-18T13:28:36.425+0000] {logging_mixin.py:188} INFO - [2024-06-18T13:28:36.424+0000] {dagbag.py:355} ERROR - Failed to import: /opt/airflow/dags/first_python_dag.py
Traceback (most recent call last):
  File "/home/airflow/.local/lib/python3.12/site-packages/airflow/models/dagbag.py", line 351, in parse
    loader.exec_module(new_module)
  File "<frozen importlib._bootstrap_external>", line 991, in exec_module
  File "<frozen importlib._bootstrap_external>", line 1129, in get_code
  File "<frozen importlib._bootstrap_external>", line 1059, in source_to_code
  File "<frozen importlib._bootstrap>", line 488, in _call_with_frames_removed
  File "/opt/airflow/dags/first_python_dag.py", line 15
    )
     ^
SyntaxError: expected ':'
[2024-06-18T13:28:36.425+0000] {processor.py:842} WARNING - No viable dags retrieved from /opt/airflow/dags/first_python_dag.py
[2024-06-18T13:28:36.437+0000] {processor.py:183} INFO - Processing /opt/airflow/dags/first_python_dag.py took 0.023 seconds
[2024-06-18T13:29:06.656+0000] {processor.py:161} INFO - Started process (PID=4523) to work on /opt/airflow/dags/first_python_dag.py
[2024-06-18T13:29:06.656+0000] {processor.py:830} INFO - Processing file /opt/airflow/dags/first_python_dag.py for tasks to queue
[2024-06-18T13:29:06.657+0000] {logging_mixin.py:188} INFO - [2024-06-18T13:29:06.657+0000] {dagbag.py:545} INFO - Filling up the DagBag from /opt/airflow/dags/first_python_dag.py
[2024-06-18T13:29:06.659+0000] {logging_mixin.py:188} INFO - [2024-06-18T13:29:06.658+0000] {dagbag.py:355} ERROR - Failed to import: /opt/airflow/dags/first_python_dag.py
Traceback (most recent call last):
  File "/home/airflow/.local/lib/python3.12/site-packages/airflow/models/dagbag.py", line 351, in parse
    loader.exec_module(new_module)
  File "<frozen importlib._bootstrap_external>", line 991, in exec_module
  File "<frozen importlib._bootstrap_external>", line 1129, in get_code
  File "<frozen importlib._bootstrap_external>", line 1059, in source_to_code
  File "<frozen importlib._bootstrap>", line 488, in _call_with_frames_removed
  File "/opt/airflow/dags/first_python_dag.py", line 15
    )
     ^
SyntaxError: expected ':'
[2024-06-18T13:29:06.659+0000] {processor.py:842} WARNING - No viable dags retrieved from /opt/airflow/dags/first_python_dag.py
[2024-06-18T13:29:06.669+0000] {processor.py:183} INFO - Processing /opt/airflow/dags/first_python_dag.py took 0.018 seconds
[2024-06-18T13:29:36.886+0000] {processor.py:161} INFO - Started process (PID=4539) to work on /opt/airflow/dags/first_python_dag.py
[2024-06-18T13:29:36.888+0000] {processor.py:830} INFO - Processing file /opt/airflow/dags/first_python_dag.py for tasks to queue
[2024-06-18T13:29:36.888+0000] {logging_mixin.py:188} INFO - [2024-06-18T13:29:36.888+0000] {dagbag.py:545} INFO - Filling up the DagBag from /opt/airflow/dags/first_python_dag.py
[2024-06-18T13:29:36.890+0000] {logging_mixin.py:188} INFO - [2024-06-18T13:29:36.889+0000] {dagbag.py:355} ERROR - Failed to import: /opt/airflow/dags/first_python_dag.py
Traceback (most recent call last):
  File "/home/airflow/.local/lib/python3.12/site-packages/airflow/models/dagbag.py", line 351, in parse
    loader.exec_module(new_module)
  File "<frozen importlib._bootstrap_external>", line 991, in exec_module
  File "<frozen importlib._bootstrap_external>", line 1129, in get_code
  File "<frozen importlib._bootstrap_external>", line 1059, in source_to_code
  File "<frozen importlib._bootstrap>", line 488, in _call_with_frames_removed
  File "/opt/airflow/dags/first_python_dag.py", line 15
    )
     ^
SyntaxError: expected ':'
[2024-06-18T13:29:36.890+0000] {processor.py:842} WARNING - No viable dags retrieved from /opt/airflow/dags/first_python_dag.py
[2024-06-18T13:29:36.901+0000] {processor.py:183} INFO - Processing /opt/airflow/dags/first_python_dag.py took 0.019 seconds
[2024-06-18T13:30:07.113+0000] {processor.py:161} INFO - Started process (PID=4555) to work on /opt/airflow/dags/first_python_dag.py
[2024-06-18T13:30:07.113+0000] {processor.py:830} INFO - Processing file /opt/airflow/dags/first_python_dag.py for tasks to queue
[2024-06-18T13:30:07.114+0000] {logging_mixin.py:188} INFO - [2024-06-18T13:30:07.114+0000] {dagbag.py:545} INFO - Filling up the DagBag from /opt/airflow/dags/first_python_dag.py
[2024-06-18T13:30:07.117+0000] {logging_mixin.py:188} INFO - [2024-06-18T13:30:07.116+0000] {dagbag.py:355} ERROR - Failed to import: /opt/airflow/dags/first_python_dag.py
Traceback (most recent call last):
  File "/home/airflow/.local/lib/python3.12/site-packages/airflow/models/dagbag.py", line 351, in parse
    loader.exec_module(new_module)
  File "<frozen importlib._bootstrap_external>", line 991, in exec_module
  File "<frozen importlib._bootstrap_external>", line 1129, in get_code
  File "<frozen importlib._bootstrap_external>", line 1059, in source_to_code
  File "<frozen importlib._bootstrap>", line 488, in _call_with_frames_removed
  File "/opt/airflow/dags/first_python_dag.py", line 15
    )
     ^
SyntaxError: expected ':'
[2024-06-18T13:30:07.117+0000] {processor.py:842} WARNING - No viable dags retrieved from /opt/airflow/dags/first_python_dag.py
[2024-06-18T13:30:07.130+0000] {processor.py:183} INFO - Processing /opt/airflow/dags/first_python_dag.py took 0.024 seconds
[2024-06-18T13:30:37.343+0000] {processor.py:161} INFO - Started process (PID=4571) to work on /opt/airflow/dags/first_python_dag.py
[2024-06-18T13:30:37.344+0000] {processor.py:830} INFO - Processing file /opt/airflow/dags/first_python_dag.py for tasks to queue
[2024-06-18T13:30:37.344+0000] {logging_mixin.py:188} INFO - [2024-06-18T13:30:37.344+0000] {dagbag.py:545} INFO - Filling up the DagBag from /opt/airflow/dags/first_python_dag.py
[2024-06-18T13:30:37.347+0000] {logging_mixin.py:188} INFO - [2024-06-18T13:30:37.346+0000] {dagbag.py:355} ERROR - Failed to import: /opt/airflow/dags/first_python_dag.py
Traceback (most recent call last):
  File "/home/airflow/.local/lib/python3.12/site-packages/airflow/models/dagbag.py", line 351, in parse
    loader.exec_module(new_module)
  File "<frozen importlib._bootstrap_external>", line 991, in exec_module
  File "<frozen importlib._bootstrap_external>", line 1129, in get_code
  File "<frozen importlib._bootstrap_external>", line 1059, in source_to_code
  File "<frozen importlib._bootstrap>", line 488, in _call_with_frames_removed
  File "/opt/airflow/dags/first_python_dag.py", line 15
    )
     ^
SyntaxError: expected ':'
[2024-06-18T13:30:37.347+0000] {processor.py:842} WARNING - No viable dags retrieved from /opt/airflow/dags/first_python_dag.py
[2024-06-18T13:30:37.359+0000] {processor.py:183} INFO - Processing /opt/airflow/dags/first_python_dag.py took 0.020 seconds
[2024-06-18T13:31:07.585+0000] {processor.py:161} INFO - Started process (PID=4587) to work on /opt/airflow/dags/first_python_dag.py
[2024-06-18T13:31:07.587+0000] {processor.py:830} INFO - Processing file /opt/airflow/dags/first_python_dag.py for tasks to queue
[2024-06-18T13:31:07.587+0000] {logging_mixin.py:188} INFO - [2024-06-18T13:31:07.587+0000] {dagbag.py:545} INFO - Filling up the DagBag from /opt/airflow/dags/first_python_dag.py
[2024-06-18T13:31:07.589+0000] {logging_mixin.py:188} INFO - [2024-06-18T13:31:07.588+0000] {dagbag.py:355} ERROR - Failed to import: /opt/airflow/dags/first_python_dag.py
Traceback (most recent call last):
  File "/home/airflow/.local/lib/python3.12/site-packages/airflow/models/dagbag.py", line 351, in parse
    loader.exec_module(new_module)
  File "<frozen importlib._bootstrap_external>", line 991, in exec_module
  File "<frozen importlib._bootstrap_external>", line 1129, in get_code
  File "<frozen importlib._bootstrap_external>", line 1059, in source_to_code
  File "<frozen importlib._bootstrap>", line 488, in _call_with_frames_removed
  File "/opt/airflow/dags/first_python_dag.py", line 15
    )
     ^
SyntaxError: expected ':'
[2024-06-18T13:31:07.589+0000] {processor.py:842} WARNING - No viable dags retrieved from /opt/airflow/dags/first_python_dag.py
[2024-06-18T13:31:07.606+0000] {processor.py:183} INFO - Processing /opt/airflow/dags/first_python_dag.py took 0.025 seconds
[2024-06-18T13:31:37.824+0000] {processor.py:161} INFO - Started process (PID=4603) to work on /opt/airflow/dags/first_python_dag.py
[2024-06-18T13:31:37.825+0000] {processor.py:830} INFO - Processing file /opt/airflow/dags/first_python_dag.py for tasks to queue
[2024-06-18T13:31:37.825+0000] {logging_mixin.py:188} INFO - [2024-06-18T13:31:37.825+0000] {dagbag.py:545} INFO - Filling up the DagBag from /opt/airflow/dags/first_python_dag.py
[2024-06-18T13:31:37.827+0000] {logging_mixin.py:188} INFO - [2024-06-18T13:31:37.826+0000] {dagbag.py:355} ERROR - Failed to import: /opt/airflow/dags/first_python_dag.py
Traceback (most recent call last):
  File "/home/airflow/.local/lib/python3.12/site-packages/airflow/models/dagbag.py", line 351, in parse
    loader.exec_module(new_module)
  File "<frozen importlib._bootstrap_external>", line 991, in exec_module
  File "<frozen importlib._bootstrap_external>", line 1129, in get_code
  File "<frozen importlib._bootstrap_external>", line 1059, in source_to_code
  File "<frozen importlib._bootstrap>", line 488, in _call_with_frames_removed
  File "/opt/airflow/dags/first_python_dag.py", line 15
    )
     ^
SyntaxError: expected ':'
[2024-06-18T13:31:37.827+0000] {processor.py:842} WARNING - No viable dags retrieved from /opt/airflow/dags/first_python_dag.py
[2024-06-18T13:31:37.838+0000] {processor.py:183} INFO - Processing /opt/airflow/dags/first_python_dag.py took 0.018 seconds
[2024-06-18T13:32:08.040+0000] {processor.py:161} INFO - Started process (PID=4619) to work on /opt/airflow/dags/first_python_dag.py
[2024-06-18T13:32:08.042+0000] {processor.py:830} INFO - Processing file /opt/airflow/dags/first_python_dag.py for tasks to queue
[2024-06-18T13:32:08.043+0000] {logging_mixin.py:188} INFO - [2024-06-18T13:32:08.043+0000] {dagbag.py:545} INFO - Filling up the DagBag from /opt/airflow/dags/first_python_dag.py
[2024-06-18T13:32:08.046+0000] {logging_mixin.py:188} INFO - [2024-06-18T13:32:08.045+0000] {dagbag.py:355} ERROR - Failed to import: /opt/airflow/dags/first_python_dag.py
Traceback (most recent call last):
  File "/home/airflow/.local/lib/python3.12/site-packages/airflow/models/dagbag.py", line 351, in parse
    loader.exec_module(new_module)
  File "<frozen importlib._bootstrap_external>", line 991, in exec_module
  File "<frozen importlib._bootstrap_external>", line 1129, in get_code
  File "<frozen importlib._bootstrap_external>", line 1059, in source_to_code
  File "<frozen importlib._bootstrap>", line 488, in _call_with_frames_removed
  File "/opt/airflow/dags/first_python_dag.py", line 15
    )
     ^
SyntaxError: expected ':'
[2024-06-18T13:32:08.046+0000] {processor.py:842} WARNING - No viable dags retrieved from /opt/airflow/dags/first_python_dag.py
[2024-06-18T13:32:08.058+0000] {processor.py:183} INFO - Processing /opt/airflow/dags/first_python_dag.py took 0.026 seconds
[2024-06-18T13:32:38.258+0000] {processor.py:161} INFO - Started process (PID=4635) to work on /opt/airflow/dags/first_python_dag.py
[2024-06-18T13:32:38.258+0000] {processor.py:830} INFO - Processing file /opt/airflow/dags/first_python_dag.py for tasks to queue
[2024-06-18T13:32:38.259+0000] {logging_mixin.py:188} INFO - [2024-06-18T13:32:38.259+0000] {dagbag.py:545} INFO - Filling up the DagBag from /opt/airflow/dags/first_python_dag.py
[2024-06-18T13:32:38.260+0000] {logging_mixin.py:188} INFO - [2024-06-18T13:32:38.260+0000] {dagbag.py:355} ERROR - Failed to import: /opt/airflow/dags/first_python_dag.py
Traceback (most recent call last):
  File "/home/airflow/.local/lib/python3.12/site-packages/airflow/models/dagbag.py", line 351, in parse
    loader.exec_module(new_module)
  File "<frozen importlib._bootstrap_external>", line 991, in exec_module
  File "<frozen importlib._bootstrap_external>", line 1129, in get_code
  File "<frozen importlib._bootstrap_external>", line 1059, in source_to_code
  File "<frozen importlib._bootstrap>", line 488, in _call_with_frames_removed
  File "/opt/airflow/dags/first_python_dag.py", line 15
    )
     ^
SyntaxError: expected ':'
[2024-06-18T13:32:38.261+0000] {processor.py:842} WARNING - No viable dags retrieved from /opt/airflow/dags/first_python_dag.py
[2024-06-18T13:32:38.272+0000] {processor.py:183} INFO - Processing /opt/airflow/dags/first_python_dag.py took 0.020 seconds
[2024-06-18T13:33:08.490+0000] {processor.py:161} INFO - Started process (PID=4651) to work on /opt/airflow/dags/first_python_dag.py
[2024-06-18T13:33:08.492+0000] {processor.py:830} INFO - Processing file /opt/airflow/dags/first_python_dag.py for tasks to queue
[2024-06-18T13:33:08.493+0000] {logging_mixin.py:188} INFO - [2024-06-18T13:33:08.493+0000] {dagbag.py:545} INFO - Filling up the DagBag from /opt/airflow/dags/first_python_dag.py
[2024-06-18T13:33:08.495+0000] {logging_mixin.py:188} INFO - [2024-06-18T13:33:08.494+0000] {dagbag.py:355} ERROR - Failed to import: /opt/airflow/dags/first_python_dag.py
Traceback (most recent call last):
  File "/home/airflow/.local/lib/python3.12/site-packages/airflow/models/dagbag.py", line 351, in parse
    loader.exec_module(new_module)
  File "<frozen importlib._bootstrap_external>", line 991, in exec_module
  File "<frozen importlib._bootstrap_external>", line 1129, in get_code
  File "<frozen importlib._bootstrap_external>", line 1059, in source_to_code
  File "<frozen importlib._bootstrap>", line 488, in _call_with_frames_removed
  File "/opt/airflow/dags/first_python_dag.py", line 15
    )
     ^
SyntaxError: expected ':'
[2024-06-18T13:33:08.495+0000] {processor.py:842} WARNING - No viable dags retrieved from /opt/airflow/dags/first_python_dag.py
[2024-06-18T13:33:08.505+0000] {processor.py:183} INFO - Processing /opt/airflow/dags/first_python_dag.py took 0.020 seconds
[2024-06-18T13:33:38.740+0000] {processor.py:161} INFO - Started process (PID=4667) to work on /opt/airflow/dags/first_python_dag.py
[2024-06-18T13:33:38.740+0000] {processor.py:830} INFO - Processing file /opt/airflow/dags/first_python_dag.py for tasks to queue
[2024-06-18T13:33:38.740+0000] {logging_mixin.py:188} INFO - [2024-06-18T13:33:38.740+0000] {dagbag.py:545} INFO - Filling up the DagBag from /opt/airflow/dags/first_python_dag.py
[2024-06-18T13:33:38.742+0000] {logging_mixin.py:188} INFO - [2024-06-18T13:33:38.742+0000] {dagbag.py:355} ERROR - Failed to import: /opt/airflow/dags/first_python_dag.py
Traceback (most recent call last):
  File "/home/airflow/.local/lib/python3.12/site-packages/airflow/models/dagbag.py", line 351, in parse
    loader.exec_module(new_module)
  File "<frozen importlib._bootstrap_external>", line 991, in exec_module
  File "<frozen importlib._bootstrap_external>", line 1129, in get_code
  File "<frozen importlib._bootstrap_external>", line 1059, in source_to_code
  File "<frozen importlib._bootstrap>", line 488, in _call_with_frames_removed
  File "/opt/airflow/dags/first_python_dag.py", line 15
    )
     ^
SyntaxError: expected ':'
[2024-06-18T13:33:38.742+0000] {processor.py:842} WARNING - No viable dags retrieved from /opt/airflow/dags/first_python_dag.py
[2024-06-18T13:33:38.754+0000] {processor.py:183} INFO - Processing /opt/airflow/dags/first_python_dag.py took 0.019 seconds
[2024-06-18T13:34:08.949+0000] {processor.py:161} INFO - Started process (PID=4683) to work on /opt/airflow/dags/first_python_dag.py
[2024-06-18T13:34:08.951+0000] {processor.py:830} INFO - Processing file /opt/airflow/dags/first_python_dag.py for tasks to queue
[2024-06-18T13:34:08.952+0000] {logging_mixin.py:188} INFO - [2024-06-18T13:34:08.951+0000] {dagbag.py:545} INFO - Filling up the DagBag from /opt/airflow/dags/first_python_dag.py
[2024-06-18T13:34:08.954+0000] {logging_mixin.py:188} INFO - [2024-06-18T13:34:08.953+0000] {dagbag.py:355} ERROR - Failed to import: /opt/airflow/dags/first_python_dag.py
Traceback (most recent call last):
  File "/home/airflow/.local/lib/python3.12/site-packages/airflow/models/dagbag.py", line 351, in parse
    loader.exec_module(new_module)
  File "<frozen importlib._bootstrap_external>", line 991, in exec_module
  File "<frozen importlib._bootstrap_external>", line 1129, in get_code
  File "<frozen importlib._bootstrap_external>", line 1059, in source_to_code
  File "<frozen importlib._bootstrap>", line 488, in _call_with_frames_removed
  File "/opt/airflow/dags/first_python_dag.py", line 15
    )
     ^
SyntaxError: expected ':'
[2024-06-18T13:34:08.954+0000] {processor.py:842} WARNING - No viable dags retrieved from /opt/airflow/dags/first_python_dag.py
[2024-06-18T13:34:08.966+0000] {processor.py:183} INFO - Processing /opt/airflow/dags/first_python_dag.py took 0.022 seconds
[2024-06-18T13:34:39.170+0000] {processor.py:161} INFO - Started process (PID=4699) to work on /opt/airflow/dags/first_python_dag.py
[2024-06-18T13:34:39.171+0000] {processor.py:830} INFO - Processing file /opt/airflow/dags/first_python_dag.py for tasks to queue
[2024-06-18T13:34:39.172+0000] {logging_mixin.py:188} INFO - [2024-06-18T13:34:39.171+0000] {dagbag.py:545} INFO - Filling up the DagBag from /opt/airflow/dags/first_python_dag.py
[2024-06-18T13:34:39.173+0000] {logging_mixin.py:188} INFO - [2024-06-18T13:34:39.173+0000] {dagbag.py:355} ERROR - Failed to import: /opt/airflow/dags/first_python_dag.py
Traceback (most recent call last):
  File "/home/airflow/.local/lib/python3.12/site-packages/airflow/models/dagbag.py", line 351, in parse
    loader.exec_module(new_module)
  File "<frozen importlib._bootstrap_external>", line 991, in exec_module
  File "<frozen importlib._bootstrap_external>", line 1129, in get_code
  File "<frozen importlib._bootstrap_external>", line 1059, in source_to_code
  File "<frozen importlib._bootstrap>", line 488, in _call_with_frames_removed
  File "/opt/airflow/dags/first_python_dag.py", line 15
    )
     ^
SyntaxError: expected ':'
[2024-06-18T13:34:39.174+0000] {processor.py:842} WARNING - No viable dags retrieved from /opt/airflow/dags/first_python_dag.py
[2024-06-18T13:34:39.186+0000] {processor.py:183} INFO - Processing /opt/airflow/dags/first_python_dag.py took 0.020 seconds
[2024-06-18T13:35:09.385+0000] {processor.py:161} INFO - Started process (PID=4715) to work on /opt/airflow/dags/first_python_dag.py
[2024-06-18T13:35:09.387+0000] {processor.py:830} INFO - Processing file /opt/airflow/dags/first_python_dag.py for tasks to queue
[2024-06-18T13:35:09.388+0000] {logging_mixin.py:188} INFO - [2024-06-18T13:35:09.388+0000] {dagbag.py:545} INFO - Filling up the DagBag from /opt/airflow/dags/first_python_dag.py
[2024-06-18T13:35:09.391+0000] {logging_mixin.py:188} INFO - [2024-06-18T13:35:09.390+0000] {dagbag.py:355} ERROR - Failed to import: /opt/airflow/dags/first_python_dag.py
Traceback (most recent call last):
  File "/home/airflow/.local/lib/python3.12/site-packages/airflow/models/dagbag.py", line 351, in parse
    loader.exec_module(new_module)
  File "<frozen importlib._bootstrap_external>", line 991, in exec_module
  File "<frozen importlib._bootstrap_external>", line 1129, in get_code
  File "<frozen importlib._bootstrap_external>", line 1059, in source_to_code
  File "<frozen importlib._bootstrap>", line 488, in _call_with_frames_removed
  File "/opt/airflow/dags/first_python_dag.py", line 15
    )
     ^
SyntaxError: expected ':'
[2024-06-18T13:35:09.391+0000] {processor.py:842} WARNING - No viable dags retrieved from /opt/airflow/dags/first_python_dag.py
[2024-06-18T13:35:09.403+0000] {processor.py:183} INFO - Processing /opt/airflow/dags/first_python_dag.py took 0.022 seconds
[2024-06-18T13:35:39.608+0000] {processor.py:161} INFO - Started process (PID=4731) to work on /opt/airflow/dags/first_python_dag.py
[2024-06-18T13:35:39.608+0000] {processor.py:830} INFO - Processing file /opt/airflow/dags/first_python_dag.py for tasks to queue
[2024-06-18T13:35:39.610+0000] {logging_mixin.py:188} INFO - [2024-06-18T13:35:39.610+0000] {dagbag.py:545} INFO - Filling up the DagBag from /opt/airflow/dags/first_python_dag.py
[2024-06-18T13:35:39.614+0000] {logging_mixin.py:188} INFO - [2024-06-18T13:35:39.612+0000] {dagbag.py:355} ERROR - Failed to import: /opt/airflow/dags/first_python_dag.py
Traceback (most recent call last):
  File "/home/airflow/.local/lib/python3.12/site-packages/airflow/models/dagbag.py", line 351, in parse
    loader.exec_module(new_module)
  File "<frozen importlib._bootstrap_external>", line 991, in exec_module
  File "<frozen importlib._bootstrap_external>", line 1129, in get_code
  File "<frozen importlib._bootstrap_external>", line 1059, in source_to_code
  File "<frozen importlib._bootstrap>", line 488, in _call_with_frames_removed
  File "/opt/airflow/dags/first_python_dag.py", line 15
    )
     ^
SyntaxError: expected ':'
[2024-06-18T13:35:39.614+0000] {processor.py:842} WARNING - No viable dags retrieved from /opt/airflow/dags/first_python_dag.py
[2024-06-18T13:35:39.635+0000] {processor.py:183} INFO - Processing /opt/airflow/dags/first_python_dag.py took 0.034 seconds
[2024-06-18T13:36:09.828+0000] {processor.py:161} INFO - Started process (PID=4747) to work on /opt/airflow/dags/first_python_dag.py
[2024-06-18T13:36:09.830+0000] {processor.py:830} INFO - Processing file /opt/airflow/dags/first_python_dag.py for tasks to queue
[2024-06-18T13:36:09.831+0000] {logging_mixin.py:188} INFO - [2024-06-18T13:36:09.830+0000] {dagbag.py:545} INFO - Filling up the DagBag from /opt/airflow/dags/first_python_dag.py
[2024-06-18T13:36:09.832+0000] {logging_mixin.py:188} INFO - [2024-06-18T13:36:09.832+0000] {dagbag.py:355} ERROR - Failed to import: /opt/airflow/dags/first_python_dag.py
Traceback (most recent call last):
  File "/home/airflow/.local/lib/python3.12/site-packages/airflow/models/dagbag.py", line 351, in parse
    loader.exec_module(new_module)
  File "<frozen importlib._bootstrap_external>", line 991, in exec_module
  File "<frozen importlib._bootstrap_external>", line 1129, in get_code
  File "<frozen importlib._bootstrap_external>", line 1059, in source_to_code
  File "<frozen importlib._bootstrap>", line 488, in _call_with_frames_removed
  File "/opt/airflow/dags/first_python_dag.py", line 15
    )
     ^
SyntaxError: expected ':'
[2024-06-18T13:36:09.833+0000] {processor.py:842} WARNING - No viable dags retrieved from /opt/airflow/dags/first_python_dag.py
[2024-06-18T13:36:09.845+0000] {processor.py:183} INFO - Processing /opt/airflow/dags/first_python_dag.py took 0.023 seconds
[2024-06-18T13:36:40.039+0000] {processor.py:161} INFO - Started process (PID=4763) to work on /opt/airflow/dags/first_python_dag.py
[2024-06-18T13:36:40.040+0000] {processor.py:830} INFO - Processing file /opt/airflow/dags/first_python_dag.py for tasks to queue
[2024-06-18T13:36:40.040+0000] {logging_mixin.py:188} INFO - [2024-06-18T13:36:40.040+0000] {dagbag.py:545} INFO - Filling up the DagBag from /opt/airflow/dags/first_python_dag.py
[2024-06-18T13:36:40.042+0000] {logging_mixin.py:188} INFO - [2024-06-18T13:36:40.041+0000] {dagbag.py:355} ERROR - Failed to import: /opt/airflow/dags/first_python_dag.py
Traceback (most recent call last):
  File "/home/airflow/.local/lib/python3.12/site-packages/airflow/models/dagbag.py", line 351, in parse
    loader.exec_module(new_module)
  File "<frozen importlib._bootstrap_external>", line 991, in exec_module
  File "<frozen importlib._bootstrap_external>", line 1129, in get_code
  File "<frozen importlib._bootstrap_external>", line 1059, in source_to_code
  File "<frozen importlib._bootstrap>", line 488, in _call_with_frames_removed
  File "/opt/airflow/dags/first_python_dag.py", line 15
    )
     ^
SyntaxError: expected ':'
[2024-06-18T13:36:40.042+0000] {processor.py:842} WARNING - No viable dags retrieved from /opt/airflow/dags/first_python_dag.py
[2024-06-18T13:36:40.052+0000] {processor.py:183} INFO - Processing /opt/airflow/dags/first_python_dag.py took 0.018 seconds
[2024-06-18T13:37:10.274+0000] {processor.py:161} INFO - Started process (PID=4779) to work on /opt/airflow/dags/first_python_dag.py
[2024-06-18T13:37:10.276+0000] {processor.py:830} INFO - Processing file /opt/airflow/dags/first_python_dag.py for tasks to queue
[2024-06-18T13:37:10.277+0000] {logging_mixin.py:188} INFO - [2024-06-18T13:37:10.277+0000] {dagbag.py:545} INFO - Filling up the DagBag from /opt/airflow/dags/first_python_dag.py
[2024-06-18T13:37:10.279+0000] {logging_mixin.py:188} INFO - [2024-06-18T13:37:10.278+0000] {dagbag.py:355} ERROR - Failed to import: /opt/airflow/dags/first_python_dag.py
Traceback (most recent call last):
  File "/home/airflow/.local/lib/python3.12/site-packages/airflow/models/dagbag.py", line 351, in parse
    loader.exec_module(new_module)
  File "<frozen importlib._bootstrap_external>", line 991, in exec_module
  File "<frozen importlib._bootstrap_external>", line 1129, in get_code
  File "<frozen importlib._bootstrap_external>", line 1059, in source_to_code
  File "<frozen importlib._bootstrap>", line 488, in _call_with_frames_removed
  File "/opt/airflow/dags/first_python_dag.py", line 15
    )
     ^
SyntaxError: expected ':'
[2024-06-18T13:37:10.280+0000] {processor.py:842} WARNING - No viable dags retrieved from /opt/airflow/dags/first_python_dag.py
[2024-06-18T13:37:10.296+0000] {processor.py:183} INFO - Processing /opt/airflow/dags/first_python_dag.py took 0.027 seconds
[2024-06-18T13:37:40.510+0000] {processor.py:161} INFO - Started process (PID=4795) to work on /opt/airflow/dags/first_python_dag.py
[2024-06-18T13:37:40.510+0000] {processor.py:830} INFO - Processing file /opt/airflow/dags/first_python_dag.py for tasks to queue
[2024-06-18T13:37:40.511+0000] {logging_mixin.py:188} INFO - [2024-06-18T13:37:40.511+0000] {dagbag.py:545} INFO - Filling up the DagBag from /opt/airflow/dags/first_python_dag.py
[2024-06-18T13:37:40.512+0000] {logging_mixin.py:188} INFO - [2024-06-18T13:37:40.512+0000] {dagbag.py:355} ERROR - Failed to import: /opt/airflow/dags/first_python_dag.py
Traceback (most recent call last):
  File "/home/airflow/.local/lib/python3.12/site-packages/airflow/models/dagbag.py", line 351, in parse
    loader.exec_module(new_module)
  File "<frozen importlib._bootstrap_external>", line 991, in exec_module
  File "<frozen importlib._bootstrap_external>", line 1129, in get_code
  File "<frozen importlib._bootstrap_external>", line 1059, in source_to_code
  File "<frozen importlib._bootstrap>", line 488, in _call_with_frames_removed
  File "/opt/airflow/dags/first_python_dag.py", line 15
    )
     ^
SyntaxError: expected ':'
[2024-06-18T13:37:40.513+0000] {processor.py:842} WARNING - No viable dags retrieved from /opt/airflow/dags/first_python_dag.py
[2024-06-18T13:37:40.523+0000] {processor.py:183} INFO - Processing /opt/airflow/dags/first_python_dag.py took 0.017 seconds
[2024-06-18T13:38:10.756+0000] {processor.py:161} INFO - Started process (PID=4811) to work on /opt/airflow/dags/first_python_dag.py
[2024-06-18T13:38:10.757+0000] {processor.py:830} INFO - Processing file /opt/airflow/dags/first_python_dag.py for tasks to queue
[2024-06-18T13:38:10.757+0000] {logging_mixin.py:188} INFO - [2024-06-18T13:38:10.757+0000] {dagbag.py:545} INFO - Filling up the DagBag from /opt/airflow/dags/first_python_dag.py
[2024-06-18T13:38:10.759+0000] {logging_mixin.py:188} INFO - [2024-06-18T13:38:10.758+0000] {dagbag.py:355} ERROR - Failed to import: /opt/airflow/dags/first_python_dag.py
Traceback (most recent call last):
  File "/home/airflow/.local/lib/python3.12/site-packages/airflow/models/dagbag.py", line 351, in parse
    loader.exec_module(new_module)
  File "<frozen importlib._bootstrap_external>", line 991, in exec_module
  File "<frozen importlib._bootstrap_external>", line 1129, in get_code
  File "<frozen importlib._bootstrap_external>", line 1059, in source_to_code
  File "<frozen importlib._bootstrap>", line 488, in _call_with_frames_removed
  File "/opt/airflow/dags/first_python_dag.py", line 15
    )
     ^
SyntaxError: expected ':'
[2024-06-18T13:38:10.759+0000] {processor.py:842} WARNING - No viable dags retrieved from /opt/airflow/dags/first_python_dag.py
[2024-06-18T13:38:10.770+0000] {processor.py:183} INFO - Processing /opt/airflow/dags/first_python_dag.py took 0.018 seconds
[2024-06-18T13:38:41.013+0000] {processor.py:161} INFO - Started process (PID=4827) to work on /opt/airflow/dags/first_python_dag.py
[2024-06-18T13:38:41.013+0000] {processor.py:830} INFO - Processing file /opt/airflow/dags/first_python_dag.py for tasks to queue
[2024-06-18T13:38:41.014+0000] {logging_mixin.py:188} INFO - [2024-06-18T13:38:41.013+0000] {dagbag.py:545} INFO - Filling up the DagBag from /opt/airflow/dags/first_python_dag.py
[2024-06-18T13:38:41.016+0000] {logging_mixin.py:188} INFO - [2024-06-18T13:38:41.015+0000] {dagbag.py:355} ERROR - Failed to import: /opt/airflow/dags/first_python_dag.py
Traceback (most recent call last):
  File "/home/airflow/.local/lib/python3.12/site-packages/airflow/models/dagbag.py", line 351, in parse
    loader.exec_module(new_module)
  File "<frozen importlib._bootstrap_external>", line 991, in exec_module
  File "<frozen importlib._bootstrap_external>", line 1129, in get_code
  File "<frozen importlib._bootstrap_external>", line 1059, in source_to_code
  File "<frozen importlib._bootstrap>", line 488, in _call_with_frames_removed
  File "/opt/airflow/dags/first_python_dag.py", line 15
    )
     ^
SyntaxError: expected ':'
[2024-06-18T13:38:41.016+0000] {processor.py:842} WARNING - No viable dags retrieved from /opt/airflow/dags/first_python_dag.py
[2024-06-18T13:38:41.027+0000] {processor.py:183} INFO - Processing /opt/airflow/dags/first_python_dag.py took 0.019 seconds
[2024-06-18T13:39:11.243+0000] {processor.py:161} INFO - Started process (PID=4843) to work on /opt/airflow/dags/first_python_dag.py
[2024-06-18T13:39:11.244+0000] {processor.py:830} INFO - Processing file /opt/airflow/dags/first_python_dag.py for tasks to queue
[2024-06-18T13:39:11.244+0000] {logging_mixin.py:188} INFO - [2024-06-18T13:39:11.244+0000] {dagbag.py:545} INFO - Filling up the DagBag from /opt/airflow/dags/first_python_dag.py
[2024-06-18T13:39:11.245+0000] {logging_mixin.py:188} INFO - [2024-06-18T13:39:11.245+0000] {dagbag.py:355} ERROR - Failed to import: /opt/airflow/dags/first_python_dag.py
Traceback (most recent call last):
  File "/home/airflow/.local/lib/python3.12/site-packages/airflow/models/dagbag.py", line 351, in parse
    loader.exec_module(new_module)
  File "<frozen importlib._bootstrap_external>", line 991, in exec_module
  File "<frozen importlib._bootstrap_external>", line 1129, in get_code
  File "<frozen importlib._bootstrap_external>", line 1059, in source_to_code
  File "<frozen importlib._bootstrap>", line 488, in _call_with_frames_removed
  File "/opt/airflow/dags/first_python_dag.py", line 15
    )
     ^
SyntaxError: expected ':'
[2024-06-18T13:39:11.246+0000] {processor.py:842} WARNING - No viable dags retrieved from /opt/airflow/dags/first_python_dag.py
[2024-06-18T13:39:11.255+0000] {processor.py:183} INFO - Processing /opt/airflow/dags/first_python_dag.py took 0.016 seconds
[2024-06-18T13:39:41.456+0000] {processor.py:161} INFO - Started process (PID=4859) to work on /opt/airflow/dags/first_python_dag.py
[2024-06-18T13:39:41.457+0000] {processor.py:830} INFO - Processing file /opt/airflow/dags/first_python_dag.py for tasks to queue
[2024-06-18T13:39:41.457+0000] {logging_mixin.py:188} INFO - [2024-06-18T13:39:41.457+0000] {dagbag.py:545} INFO - Filling up the DagBag from /opt/airflow/dags/first_python_dag.py
[2024-06-18T13:39:41.459+0000] {logging_mixin.py:188} INFO - [2024-06-18T13:39:41.458+0000] {dagbag.py:355} ERROR - Failed to import: /opt/airflow/dags/first_python_dag.py
Traceback (most recent call last):
  File "/home/airflow/.local/lib/python3.12/site-packages/airflow/models/dagbag.py", line 351, in parse
    loader.exec_module(new_module)
  File "<frozen importlib._bootstrap_external>", line 991, in exec_module
  File "<frozen importlib._bootstrap_external>", line 1129, in get_code
  File "<frozen importlib._bootstrap_external>", line 1059, in source_to_code
  File "<frozen importlib._bootstrap>", line 488, in _call_with_frames_removed
  File "/opt/airflow/dags/first_python_dag.py", line 15
    )
     ^
SyntaxError: expected ':'
[2024-06-18T13:39:41.459+0000] {processor.py:842} WARNING - No viable dags retrieved from /opt/airflow/dags/first_python_dag.py
[2024-06-18T13:39:41.471+0000] {processor.py:183} INFO - Processing /opt/airflow/dags/first_python_dag.py took 0.021 seconds
[2024-06-18T13:40:11.686+0000] {processor.py:161} INFO - Started process (PID=4875) to work on /opt/airflow/dags/first_python_dag.py
[2024-06-18T13:40:11.688+0000] {processor.py:830} INFO - Processing file /opt/airflow/dags/first_python_dag.py for tasks to queue
[2024-06-18T13:40:11.689+0000] {logging_mixin.py:188} INFO - [2024-06-18T13:40:11.689+0000] {dagbag.py:545} INFO - Filling up the DagBag from /opt/airflow/dags/first_python_dag.py
[2024-06-18T13:40:11.692+0000] {logging_mixin.py:188} INFO - [2024-06-18T13:40:11.691+0000] {dagbag.py:355} ERROR - Failed to import: /opt/airflow/dags/first_python_dag.py
Traceback (most recent call last):
  File "/home/airflow/.local/lib/python3.12/site-packages/airflow/models/dagbag.py", line 351, in parse
    loader.exec_module(new_module)
  File "<frozen importlib._bootstrap_external>", line 991, in exec_module
  File "<frozen importlib._bootstrap_external>", line 1129, in get_code
  File "<frozen importlib._bootstrap_external>", line 1059, in source_to_code
  File "<frozen importlib._bootstrap>", line 488, in _call_with_frames_removed
  File "/opt/airflow/dags/first_python_dag.py", line 15
    )
     ^
SyntaxError: expected ':'
[2024-06-18T13:40:11.692+0000] {processor.py:842} WARNING - No viable dags retrieved from /opt/airflow/dags/first_python_dag.py
[2024-06-18T13:40:11.705+0000] {processor.py:183} INFO - Processing /opt/airflow/dags/first_python_dag.py took 0.026 seconds
[2024-06-18T13:40:41.920+0000] {processor.py:161} INFO - Started process (PID=4892) to work on /opt/airflow/dags/first_python_dag.py
[2024-06-18T13:40:41.920+0000] {processor.py:830} INFO - Processing file /opt/airflow/dags/first_python_dag.py for tasks to queue
[2024-06-18T13:40:41.921+0000] {logging_mixin.py:188} INFO - [2024-06-18T13:40:41.921+0000] {dagbag.py:545} INFO - Filling up the DagBag from /opt/airflow/dags/first_python_dag.py
[2024-06-18T13:40:41.924+0000] {logging_mixin.py:188} INFO - [2024-06-18T13:40:41.923+0000] {dagbag.py:355} ERROR - Failed to import: /opt/airflow/dags/first_python_dag.py
Traceback (most recent call last):
  File "/home/airflow/.local/lib/python3.12/site-packages/airflow/models/dagbag.py", line 351, in parse
    loader.exec_module(new_module)
  File "<frozen importlib._bootstrap_external>", line 991, in exec_module
  File "<frozen importlib._bootstrap_external>", line 1129, in get_code
  File "<frozen importlib._bootstrap_external>", line 1059, in source_to_code
  File "<frozen importlib._bootstrap>", line 488, in _call_with_frames_removed
  File "/opt/airflow/dags/first_python_dag.py", line 15
    )
     ^
SyntaxError: expected ':'
[2024-06-18T13:40:41.926+0000] {processor.py:842} WARNING - No viable dags retrieved from /opt/airflow/dags/first_python_dag.py
[2024-06-18T13:40:41.957+0000] {processor.py:183} INFO - Processing /opt/airflow/dags/first_python_dag.py took 0.044 seconds
[2024-06-18T13:41:12.165+0000] {processor.py:161} INFO - Started process (PID=4908) to work on /opt/airflow/dags/first_python_dag.py
[2024-06-18T13:41:12.168+0000] {processor.py:830} INFO - Processing file /opt/airflow/dags/first_python_dag.py for tasks to queue
[2024-06-18T13:41:12.170+0000] {logging_mixin.py:188} INFO - [2024-06-18T13:41:12.169+0000] {dagbag.py:545} INFO - Filling up the DagBag from /opt/airflow/dags/first_python_dag.py
[2024-06-18T13:41:12.174+0000] {logging_mixin.py:188} INFO - [2024-06-18T13:41:12.173+0000] {dagbag.py:355} ERROR - Failed to import: /opt/airflow/dags/first_python_dag.py
Traceback (most recent call last):
  File "/home/airflow/.local/lib/python3.12/site-packages/airflow/models/dagbag.py", line 351, in parse
    loader.exec_module(new_module)
  File "<frozen importlib._bootstrap_external>", line 991, in exec_module
  File "<frozen importlib._bootstrap_external>", line 1129, in get_code
  File "<frozen importlib._bootstrap_external>", line 1059, in source_to_code
  File "<frozen importlib._bootstrap>", line 488, in _call_with_frames_removed
  File "/opt/airflow/dags/first_python_dag.py", line 15
    )
     ^
SyntaxError: expected ':'
[2024-06-18T13:41:12.175+0000] {processor.py:842} WARNING - No viable dags retrieved from /opt/airflow/dags/first_python_dag.py
[2024-06-18T13:41:12.193+0000] {processor.py:183} INFO - Processing /opt/airflow/dags/first_python_dag.py took 0.035 seconds
[2024-06-18T13:41:42.412+0000] {processor.py:161} INFO - Started process (PID=4924) to work on /opt/airflow/dags/first_python_dag.py
[2024-06-18T13:41:42.412+0000] {processor.py:830} INFO - Processing file /opt/airflow/dags/first_python_dag.py for tasks to queue
[2024-06-18T13:41:42.413+0000] {logging_mixin.py:188} INFO - [2024-06-18T13:41:42.413+0000] {dagbag.py:545} INFO - Filling up the DagBag from /opt/airflow/dags/first_python_dag.py
[2024-06-18T13:41:42.416+0000] {logging_mixin.py:188} INFO - [2024-06-18T13:41:42.415+0000] {dagbag.py:355} ERROR - Failed to import: /opt/airflow/dags/first_python_dag.py
Traceback (most recent call last):
  File "/home/airflow/.local/lib/python3.12/site-packages/airflow/models/dagbag.py", line 351, in parse
    loader.exec_module(new_module)
  File "<frozen importlib._bootstrap_external>", line 991, in exec_module
  File "<frozen importlib._bootstrap_external>", line 1129, in get_code
  File "<frozen importlib._bootstrap_external>", line 1059, in source_to_code
  File "<frozen importlib._bootstrap>", line 488, in _call_with_frames_removed
  File "/opt/airflow/dags/first_python_dag.py", line 15
    )
     ^
SyntaxError: expected ':'
[2024-06-18T13:41:42.417+0000] {processor.py:842} WARNING - No viable dags retrieved from /opt/airflow/dags/first_python_dag.py
[2024-06-18T13:41:42.446+0000] {processor.py:183} INFO - Processing /opt/airflow/dags/first_python_dag.py took 0.040 seconds
[2024-06-18T13:42:12.645+0000] {processor.py:161} INFO - Started process (PID=4940) to work on /opt/airflow/dags/first_python_dag.py
[2024-06-18T13:42:12.647+0000] {processor.py:830} INFO - Processing file /opt/airflow/dags/first_python_dag.py for tasks to queue
[2024-06-18T13:42:12.648+0000] {logging_mixin.py:188} INFO - [2024-06-18T13:42:12.648+0000] {dagbag.py:545} INFO - Filling up the DagBag from /opt/airflow/dags/first_python_dag.py
[2024-06-18T13:42:12.650+0000] {logging_mixin.py:188} INFO - [2024-06-18T13:42:12.649+0000] {dagbag.py:355} ERROR - Failed to import: /opt/airflow/dags/first_python_dag.py
Traceback (most recent call last):
  File "/home/airflow/.local/lib/python3.12/site-packages/airflow/models/dagbag.py", line 351, in parse
    loader.exec_module(new_module)
  File "<frozen importlib._bootstrap_external>", line 991, in exec_module
  File "<frozen importlib._bootstrap_external>", line 1129, in get_code
  File "<frozen importlib._bootstrap_external>", line 1059, in source_to_code
  File "<frozen importlib._bootstrap>", line 488, in _call_with_frames_removed
  File "/opt/airflow/dags/first_python_dag.py", line 15
    )
     ^
SyntaxError: expected ':'
[2024-06-18T13:42:12.650+0000] {processor.py:842} WARNING - No viable dags retrieved from /opt/airflow/dags/first_python_dag.py
[2024-06-18T13:42:12.662+0000] {processor.py:183} INFO - Processing /opt/airflow/dags/first_python_dag.py took 0.022 seconds
[2024-06-18T13:42:42.875+0000] {processor.py:161} INFO - Started process (PID=4956) to work on /opt/airflow/dags/first_python_dag.py
[2024-06-18T13:42:42.875+0000] {processor.py:830} INFO - Processing file /opt/airflow/dags/first_python_dag.py for tasks to queue
[2024-06-18T13:42:42.876+0000] {logging_mixin.py:188} INFO - [2024-06-18T13:42:42.876+0000] {dagbag.py:545} INFO - Filling up the DagBag from /opt/airflow/dags/first_python_dag.py
[2024-06-18T13:42:42.878+0000] {logging_mixin.py:188} INFO - [2024-06-18T13:42:42.877+0000] {dagbag.py:355} ERROR - Failed to import: /opt/airflow/dags/first_python_dag.py
Traceback (most recent call last):
  File "/home/airflow/.local/lib/python3.12/site-packages/airflow/models/dagbag.py", line 351, in parse
    loader.exec_module(new_module)
  File "<frozen importlib._bootstrap_external>", line 991, in exec_module
  File "<frozen importlib._bootstrap_external>", line 1129, in get_code
  File "<frozen importlib._bootstrap_external>", line 1059, in source_to_code
  File "<frozen importlib._bootstrap>", line 488, in _call_with_frames_removed
  File "/opt/airflow/dags/first_python_dag.py", line 15
    )
     ^
SyntaxError: expected ':'
[2024-06-18T13:42:42.878+0000] {processor.py:842} WARNING - No viable dags retrieved from /opt/airflow/dags/first_python_dag.py
[2024-06-18T13:42:42.891+0000] {processor.py:183} INFO - Processing /opt/airflow/dags/first_python_dag.py took 0.022 seconds
[2024-06-18T13:43:13.092+0000] {processor.py:161} INFO - Started process (PID=4972) to work on /opt/airflow/dags/first_python_dag.py
[2024-06-18T13:43:13.094+0000] {processor.py:830} INFO - Processing file /opt/airflow/dags/first_python_dag.py for tasks to queue
[2024-06-18T13:43:13.095+0000] {logging_mixin.py:188} INFO - [2024-06-18T13:43:13.094+0000] {dagbag.py:545} INFO - Filling up the DagBag from /opt/airflow/dags/first_python_dag.py
[2024-06-18T13:43:13.097+0000] {logging_mixin.py:188} INFO - [2024-06-18T13:43:13.096+0000] {dagbag.py:355} ERROR - Failed to import: /opt/airflow/dags/first_python_dag.py
Traceback (most recent call last):
  File "/home/airflow/.local/lib/python3.12/site-packages/airflow/models/dagbag.py", line 351, in parse
    loader.exec_module(new_module)
  File "<frozen importlib._bootstrap_external>", line 991, in exec_module
  File "<frozen importlib._bootstrap_external>", line 1129, in get_code
  File "<frozen importlib._bootstrap_external>", line 1059, in source_to_code
  File "<frozen importlib._bootstrap>", line 488, in _call_with_frames_removed
  File "/opt/airflow/dags/first_python_dag.py", line 15
    )
     ^
SyntaxError: expected ':'
[2024-06-18T13:43:13.097+0000] {processor.py:842} WARNING - No viable dags retrieved from /opt/airflow/dags/first_python_dag.py
[2024-06-18T13:43:13.108+0000] {processor.py:183} INFO - Processing /opt/airflow/dags/first_python_dag.py took 0.021 seconds
[2024-06-18T13:43:43.325+0000] {processor.py:161} INFO - Started process (PID=4988) to work on /opt/airflow/dags/first_python_dag.py
[2024-06-18T13:43:43.325+0000] {processor.py:830} INFO - Processing file /opt/airflow/dags/first_python_dag.py for tasks to queue
[2024-06-18T13:43:43.326+0000] {logging_mixin.py:188} INFO - [2024-06-18T13:43:43.326+0000] {dagbag.py:545} INFO - Filling up the DagBag from /opt/airflow/dags/first_python_dag.py
[2024-06-18T13:43:43.328+0000] {logging_mixin.py:188} INFO - [2024-06-18T13:43:43.327+0000] {dagbag.py:355} ERROR - Failed to import: /opt/airflow/dags/first_python_dag.py
Traceback (most recent call last):
  File "/home/airflow/.local/lib/python3.12/site-packages/airflow/models/dagbag.py", line 351, in parse
    loader.exec_module(new_module)
  File "<frozen importlib._bootstrap_external>", line 991, in exec_module
  File "<frozen importlib._bootstrap_external>", line 1129, in get_code
  File "<frozen importlib._bootstrap_external>", line 1059, in source_to_code
  File "<frozen importlib._bootstrap>", line 488, in _call_with_frames_removed
  File "/opt/airflow/dags/first_python_dag.py", line 15
    )
     ^
SyntaxError: expected ':'
[2024-06-18T13:43:43.328+0000] {processor.py:842} WARNING - No viable dags retrieved from /opt/airflow/dags/first_python_dag.py
[2024-06-18T13:43:43.339+0000] {processor.py:183} INFO - Processing /opt/airflow/dags/first_python_dag.py took 0.020 seconds
[2024-06-18T13:44:13.537+0000] {processor.py:161} INFO - Started process (PID=5005) to work on /opt/airflow/dags/first_python_dag.py
[2024-06-18T13:44:13.538+0000] {processor.py:830} INFO - Processing file /opt/airflow/dags/first_python_dag.py for tasks to queue
[2024-06-18T13:44:13.539+0000] {logging_mixin.py:188} INFO - [2024-06-18T13:44:13.538+0000] {dagbag.py:545} INFO - Filling up the DagBag from /opt/airflow/dags/first_python_dag.py
[2024-06-18T13:44:13.540+0000] {logging_mixin.py:188} INFO - [2024-06-18T13:44:13.540+0000] {dagbag.py:355} ERROR - Failed to import: /opt/airflow/dags/first_python_dag.py
Traceback (most recent call last):
  File "/home/airflow/.local/lib/python3.12/site-packages/airflow/models/dagbag.py", line 351, in parse
    loader.exec_module(new_module)
  File "<frozen importlib._bootstrap_external>", line 991, in exec_module
  File "<frozen importlib._bootstrap_external>", line 1129, in get_code
  File "<frozen importlib._bootstrap_external>", line 1059, in source_to_code
  File "<frozen importlib._bootstrap>", line 488, in _call_with_frames_removed
  File "/opt/airflow/dags/first_python_dag.py", line 15
    )
     ^
SyntaxError: expected ':'
[2024-06-18T13:44:13.541+0000] {processor.py:842} WARNING - No viable dags retrieved from /opt/airflow/dags/first_python_dag.py
[2024-06-18T13:44:13.551+0000] {processor.py:183} INFO - Processing /opt/airflow/dags/first_python_dag.py took 0.019 seconds
[2024-06-18T13:44:43.759+0000] {processor.py:161} INFO - Started process (PID=5021) to work on /opt/airflow/dags/first_python_dag.py
[2024-06-18T13:44:43.759+0000] {processor.py:830} INFO - Processing file /opt/airflow/dags/first_python_dag.py for tasks to queue
[2024-06-18T13:44:43.760+0000] {logging_mixin.py:188} INFO - [2024-06-18T13:44:43.760+0000] {dagbag.py:545} INFO - Filling up the DagBag from /opt/airflow/dags/first_python_dag.py
[2024-06-18T13:44:43.762+0000] {logging_mixin.py:188} INFO - [2024-06-18T13:44:43.761+0000] {dagbag.py:355} ERROR - Failed to import: /opt/airflow/dags/first_python_dag.py
Traceback (most recent call last):
  File "/home/airflow/.local/lib/python3.12/site-packages/airflow/models/dagbag.py", line 351, in parse
    loader.exec_module(new_module)
  File "<frozen importlib._bootstrap_external>", line 991, in exec_module
  File "<frozen importlib._bootstrap_external>", line 1129, in get_code
  File "<frozen importlib._bootstrap_external>", line 1059, in source_to_code
  File "<frozen importlib._bootstrap>", line 488, in _call_with_frames_removed
  File "/opt/airflow/dags/first_python_dag.py", line 15
    )
     ^
SyntaxError: expected ':'
[2024-06-18T13:44:43.762+0000] {processor.py:842} WARNING - No viable dags retrieved from /opt/airflow/dags/first_python_dag.py
[2024-06-18T13:44:43.773+0000] {processor.py:183} INFO - Processing /opt/airflow/dags/first_python_dag.py took 0.021 seconds
[2024-06-18T13:45:13.982+0000] {processor.py:161} INFO - Started process (PID=5037) to work on /opt/airflow/dags/first_python_dag.py
[2024-06-18T13:45:13.984+0000] {processor.py:830} INFO - Processing file /opt/airflow/dags/first_python_dag.py for tasks to queue
[2024-06-18T13:45:13.984+0000] {logging_mixin.py:188} INFO - [2024-06-18T13:45:13.984+0000] {dagbag.py:545} INFO - Filling up the DagBag from /opt/airflow/dags/first_python_dag.py
[2024-06-18T13:45:13.986+0000] {logging_mixin.py:188} INFO - [2024-06-18T13:45:13.985+0000] {dagbag.py:355} ERROR - Failed to import: /opt/airflow/dags/first_python_dag.py
Traceback (most recent call last):
  File "/home/airflow/.local/lib/python3.12/site-packages/airflow/models/dagbag.py", line 351, in parse
    loader.exec_module(new_module)
  File "<frozen importlib._bootstrap_external>", line 991, in exec_module
  File "<frozen importlib._bootstrap_external>", line 1129, in get_code
  File "<frozen importlib._bootstrap_external>", line 1059, in source_to_code
  File "<frozen importlib._bootstrap>", line 488, in _call_with_frames_removed
  File "/opt/airflow/dags/first_python_dag.py", line 15
    )
     ^
SyntaxError: expected ':'
[2024-06-18T13:45:13.986+0000] {processor.py:842} WARNING - No viable dags retrieved from /opt/airflow/dags/first_python_dag.py
[2024-06-18T13:45:13.997+0000] {processor.py:183} INFO - Processing /opt/airflow/dags/first_python_dag.py took 0.019 seconds
[2024-06-18T13:45:44.211+0000] {processor.py:161} INFO - Started process (PID=5053) to work on /opt/airflow/dags/first_python_dag.py
[2024-06-18T13:45:44.212+0000] {processor.py:830} INFO - Processing file /opt/airflow/dags/first_python_dag.py for tasks to queue
[2024-06-18T13:45:44.213+0000] {logging_mixin.py:188} INFO - [2024-06-18T13:45:44.213+0000] {dagbag.py:545} INFO - Filling up the DagBag from /opt/airflow/dags/first_python_dag.py
[2024-06-18T13:45:44.215+0000] {logging_mixin.py:188} INFO - [2024-06-18T13:45:44.215+0000] {dagbag.py:355} ERROR - Failed to import: /opt/airflow/dags/first_python_dag.py
Traceback (most recent call last):
  File "/home/airflow/.local/lib/python3.12/site-packages/airflow/models/dagbag.py", line 351, in parse
    loader.exec_module(new_module)
  File "<frozen importlib._bootstrap_external>", line 991, in exec_module
  File "<frozen importlib._bootstrap_external>", line 1129, in get_code
  File "<frozen importlib._bootstrap_external>", line 1059, in source_to_code
  File "<frozen importlib._bootstrap>", line 488, in _call_with_frames_removed
  File "/opt/airflow/dags/first_python_dag.py", line 15
    )
     ^
SyntaxError: expected ':'
[2024-06-18T13:45:44.216+0000] {processor.py:842} WARNING - No viable dags retrieved from /opt/airflow/dags/first_python_dag.py
[2024-06-18T13:45:44.227+0000] {processor.py:183} INFO - Processing /opt/airflow/dags/first_python_dag.py took 0.021 seconds
[2024-06-18T13:46:14.458+0000] {processor.py:161} INFO - Started process (PID=5069) to work on /opt/airflow/dags/first_python_dag.py
[2024-06-18T13:46:14.458+0000] {processor.py:830} INFO - Processing file /opt/airflow/dags/first_python_dag.py for tasks to queue
[2024-06-18T13:46:14.458+0000] {logging_mixin.py:188} INFO - [2024-06-18T13:46:14.458+0000] {dagbag.py:545} INFO - Filling up the DagBag from /opt/airflow/dags/first_python_dag.py
[2024-06-18T13:46:14.460+0000] {logging_mixin.py:188} INFO - [2024-06-18T13:46:14.460+0000] {dagbag.py:355} ERROR - Failed to import: /opt/airflow/dags/first_python_dag.py
Traceback (most recent call last):
  File "/home/airflow/.local/lib/python3.12/site-packages/airflow/models/dagbag.py", line 351, in parse
    loader.exec_module(new_module)
  File "<frozen importlib._bootstrap_external>", line 991, in exec_module
  File "<frozen importlib._bootstrap_external>", line 1129, in get_code
  File "<frozen importlib._bootstrap_external>", line 1059, in source_to_code
  File "<frozen importlib._bootstrap>", line 488, in _call_with_frames_removed
  File "/opt/airflow/dags/first_python_dag.py", line 15
    )
     ^
SyntaxError: expected ':'
[2024-06-18T13:46:14.460+0000] {processor.py:842} WARNING - No viable dags retrieved from /opt/airflow/dags/first_python_dag.py
[2024-06-18T13:46:14.472+0000] {processor.py:183} INFO - Processing /opt/airflow/dags/first_python_dag.py took 0.017 seconds
[2024-06-18T13:46:44.692+0000] {processor.py:161} INFO - Started process (PID=5085) to work on /opt/airflow/dags/first_python_dag.py
[2024-06-18T13:46:44.692+0000] {processor.py:830} INFO - Processing file /opt/airflow/dags/first_python_dag.py for tasks to queue
[2024-06-18T13:46:44.693+0000] {logging_mixin.py:188} INFO - [2024-06-18T13:46:44.693+0000] {dagbag.py:545} INFO - Filling up the DagBag from /opt/airflow/dags/first_python_dag.py
[2024-06-18T13:46:44.695+0000] {logging_mixin.py:188} INFO - [2024-06-18T13:46:44.694+0000] {dagbag.py:355} ERROR - Failed to import: /opt/airflow/dags/first_python_dag.py
Traceback (most recent call last):
  File "/home/airflow/.local/lib/python3.12/site-packages/airflow/models/dagbag.py", line 351, in parse
    loader.exec_module(new_module)
  File "<frozen importlib._bootstrap_external>", line 991, in exec_module
  File "<frozen importlib._bootstrap_external>", line 1129, in get_code
  File "<frozen importlib._bootstrap_external>", line 1059, in source_to_code
  File "<frozen importlib._bootstrap>", line 488, in _call_with_frames_removed
  File "/opt/airflow/dags/first_python_dag.py", line 15
    )
     ^
SyntaxError: expected ':'
[2024-06-18T13:46:44.695+0000] {processor.py:842} WARNING - No viable dags retrieved from /opt/airflow/dags/first_python_dag.py
[2024-06-18T13:46:44.706+0000] {processor.py:183} INFO - Processing /opt/airflow/dags/first_python_dag.py took 0.020 seconds
[2024-06-18T13:47:14.934+0000] {processor.py:161} INFO - Started process (PID=5101) to work on /opt/airflow/dags/first_python_dag.py
[2024-06-18T13:47:14.934+0000] {processor.py:830} INFO - Processing file /opt/airflow/dags/first_python_dag.py for tasks to queue
[2024-06-18T13:47:14.934+0000] {logging_mixin.py:188} INFO - [2024-06-18T13:47:14.934+0000] {dagbag.py:545} INFO - Filling up the DagBag from /opt/airflow/dags/first_python_dag.py
[2024-06-18T13:47:14.947+0000] {logging_mixin.py:188} INFO - [2024-06-18T13:47:14.940+0000] {dagbag.py:355} ERROR - Failed to import: /opt/airflow/dags/first_python_dag.py
Traceback (most recent call last):
  File "/home/airflow/.local/lib/python3.12/site-packages/airflow/models/dagbag.py", line 351, in parse
    loader.exec_module(new_module)
  File "<frozen importlib._bootstrap_external>", line 991, in exec_module
  File "<frozen importlib._bootstrap_external>", line 1129, in get_code
  File "<frozen importlib._bootstrap_external>", line 1059, in source_to_code
  File "<frozen importlib._bootstrap>", line 488, in _call_with_frames_removed
  File "/opt/airflow/dags/first_python_dag.py", line 15
    )
     ^
SyntaxError: expected ':'
[2024-06-18T13:47:14.951+0000] {processor.py:842} WARNING - No viable dags retrieved from /opt/airflow/dags/first_python_dag.py
[2024-06-18T13:47:14.990+0000] {processor.py:183} INFO - Processing /opt/airflow/dags/first_python_dag.py took 0.060 seconds
[2024-06-18T13:47:16.965+0000] {processor.py:161} INFO - Started process (PID=5106) to work on /opt/airflow/dags/first_python_dag.py
[2024-06-18T13:47:16.966+0000] {processor.py:830} INFO - Processing file /opt/airflow/dags/first_python_dag.py for tasks to queue
[2024-06-18T13:47:16.966+0000] {logging_mixin.py:188} INFO - [2024-06-18T13:47:16.966+0000] {dagbag.py:545} INFO - Filling up the DagBag from /opt/airflow/dags/first_python_dag.py
[2024-06-18T13:47:16.968+0000] {logging_mixin.py:188} INFO - [2024-06-18T13:47:16.967+0000] {dagbag.py:355} ERROR - Failed to import: /opt/airflow/dags/first_python_dag.py
Traceback (most recent call last):
  File "/home/airflow/.local/lib/python3.12/site-packages/airflow/models/dagbag.py", line 351, in parse
    loader.exec_module(new_module)
  File "<frozen importlib._bootstrap_external>", line 991, in exec_module
  File "<frozen importlib._bootstrap_external>", line 1129, in get_code
  File "<frozen importlib._bootstrap_external>", line 1059, in source_to_code
  File "<frozen importlib._bootstrap>", line 488, in _call_with_frames_removed
  File "/opt/airflow/dags/first_python_dag.py", line 16
    )
    ^
SyntaxError: positional argument follows keyword argument
[2024-06-18T13:47:16.968+0000] {processor.py:842} WARNING - No viable dags retrieved from /opt/airflow/dags/first_python_dag.py
[2024-06-18T13:47:16.980+0000] {processor.py:183} INFO - Processing /opt/airflow/dags/first_python_dag.py took 0.021 seconds
[2024-06-18T13:47:25.025+0000] {processor.py:161} INFO - Started process (PID=5116) to work on /opt/airflow/dags/first_python_dag.py
[2024-06-18T13:47:25.026+0000] {processor.py:830} INFO - Processing file /opt/airflow/dags/first_python_dag.py for tasks to queue
[2024-06-18T13:47:25.026+0000] {logging_mixin.py:188} INFO - [2024-06-18T13:47:25.026+0000] {dagbag.py:545} INFO - Filling up the DagBag from /opt/airflow/dags/first_python_dag.py
[2024-06-18T13:47:25.028+0000] {logging_mixin.py:188} INFO - [2024-06-18T13:47:25.027+0000] {dagbag.py:355} ERROR - Failed to import: /opt/airflow/dags/first_python_dag.py
Traceback (most recent call last):
  File "/home/airflow/.local/lib/python3.12/site-packages/airflow/models/dagbag.py", line 351, in parse
    loader.exec_module(new_module)
  File "<frozen importlib._bootstrap_external>", line 991, in exec_module
  File "<frozen importlib._bootstrap_external>", line 1129, in get_code
  File "<frozen importlib._bootstrap_external>", line 1059, in source_to_code
  File "<frozen importlib._bootstrap>", line 488, in _call_with_frames_removed
  File "/opt/airflow/dags/first_python_dag.py", line 16
    )
    ^
SyntaxError: positional argument follows keyword argument
[2024-06-18T13:47:25.028+0000] {processor.py:842} WARNING - No viable dags retrieved from /opt/airflow/dags/first_python_dag.py
[2024-06-18T13:47:25.041+0000] {processor.py:183} INFO - Processing /opt/airflow/dags/first_python_dag.py took 0.023 seconds
[2024-06-18T13:47:55.277+0000] {processor.py:161} INFO - Started process (PID=5132) to work on /opt/airflow/dags/first_python_dag.py
[2024-06-18T13:47:55.282+0000] {processor.py:830} INFO - Processing file /opt/airflow/dags/first_python_dag.py for tasks to queue
[2024-06-18T13:47:55.285+0000] {logging_mixin.py:188} INFO - [2024-06-18T13:47:55.284+0000] {dagbag.py:545} INFO - Filling up the DagBag from /opt/airflow/dags/first_python_dag.py
[2024-06-18T13:47:55.300+0000] {logging_mixin.py:188} INFO - [2024-06-18T13:47:55.294+0000] {dagbag.py:355} ERROR - Failed to import: /opt/airflow/dags/first_python_dag.py
Traceback (most recent call last):
  File "/home/airflow/.local/lib/python3.12/site-packages/airflow/models/dagbag.py", line 351, in parse
    loader.exec_module(new_module)
  File "<frozen importlib._bootstrap_external>", line 991, in exec_module
  File "<frozen importlib._bootstrap_external>", line 1129, in get_code
  File "<frozen importlib._bootstrap_external>", line 1059, in source_to_code
  File "<frozen importlib._bootstrap>", line 488, in _call_with_frames_removed
  File "/opt/airflow/dags/first_python_dag.py", line 16
    )
    ^
SyntaxError: positional argument follows keyword argument
[2024-06-18T13:47:55.303+0000] {processor.py:842} WARNING - No viable dags retrieved from /opt/airflow/dags/first_python_dag.py
[2024-06-18T13:47:55.328+0000] {processor.py:183} INFO - Processing /opt/airflow/dags/first_python_dag.py took 0.080 seconds
[2024-06-18T13:48:25.438+0000] {processor.py:161} INFO - Started process (PID=5148) to work on /opt/airflow/dags/first_python_dag.py
[2024-06-18T13:48:25.438+0000] {processor.py:830} INFO - Processing file /opt/airflow/dags/first_python_dag.py for tasks to queue
[2024-06-18T13:48:25.439+0000] {logging_mixin.py:188} INFO - [2024-06-18T13:48:25.439+0000] {dagbag.py:545} INFO - Filling up the DagBag from /opt/airflow/dags/first_python_dag.py
[2024-06-18T13:48:25.441+0000] {logging_mixin.py:188} INFO - [2024-06-18T13:48:25.440+0000] {dagbag.py:355} ERROR - Failed to import: /opt/airflow/dags/first_python_dag.py
Traceback (most recent call last):
  File "/home/airflow/.local/lib/python3.12/site-packages/airflow/models/dagbag.py", line 351, in parse
    loader.exec_module(new_module)
  File "<frozen importlib._bootstrap_external>", line 991, in exec_module
  File "<frozen importlib._bootstrap_external>", line 1129, in get_code
  File "<frozen importlib._bootstrap_external>", line 1059, in source_to_code
  File "<frozen importlib._bootstrap>", line 488, in _call_with_frames_removed
  File "/opt/airflow/dags/first_python_dag.py", line 16
    )
    ^
SyntaxError: positional argument follows keyword argument
[2024-06-18T13:48:25.441+0000] {processor.py:842} WARNING - No viable dags retrieved from /opt/airflow/dags/first_python_dag.py
[2024-06-18T13:48:25.452+0000] {processor.py:183} INFO - Processing /opt/airflow/dags/first_python_dag.py took 0.022 seconds
[2024-06-18T13:48:55.695+0000] {processor.py:161} INFO - Started process (PID=5164) to work on /opt/airflow/dags/first_python_dag.py
[2024-06-18T13:48:55.697+0000] {processor.py:830} INFO - Processing file /opt/airflow/dags/first_python_dag.py for tasks to queue
[2024-06-18T13:48:55.698+0000] {logging_mixin.py:188} INFO - [2024-06-18T13:48:55.698+0000] {dagbag.py:545} INFO - Filling up the DagBag from /opt/airflow/dags/first_python_dag.py
[2024-06-18T13:48:55.701+0000] {logging_mixin.py:188} INFO - [2024-06-18T13:48:55.700+0000] {dagbag.py:355} ERROR - Failed to import: /opt/airflow/dags/first_python_dag.py
Traceback (most recent call last):
  File "/home/airflow/.local/lib/python3.12/site-packages/airflow/models/dagbag.py", line 351, in parse
    loader.exec_module(new_module)
  File "<frozen importlib._bootstrap_external>", line 991, in exec_module
  File "<frozen importlib._bootstrap_external>", line 1129, in get_code
  File "<frozen importlib._bootstrap_external>", line 1059, in source_to_code
  File "<frozen importlib._bootstrap>", line 488, in _call_with_frames_removed
  File "/opt/airflow/dags/first_python_dag.py", line 16
    )
    ^
SyntaxError: positional argument follows keyword argument
[2024-06-18T13:48:55.702+0000] {processor.py:842} WARNING - No viable dags retrieved from /opt/airflow/dags/first_python_dag.py
[2024-06-18T13:48:55.714+0000] {processor.py:183} INFO - Processing /opt/airflow/dags/first_python_dag.py took 0.027 seconds
[2024-06-18T13:49:25.903+0000] {processor.py:161} INFO - Started process (PID=5180) to work on /opt/airflow/dags/first_python_dag.py
[2024-06-18T13:49:25.904+0000] {processor.py:830} INFO - Processing file /opt/airflow/dags/first_python_dag.py for tasks to queue
[2024-06-18T13:49:25.904+0000] {logging_mixin.py:188} INFO - [2024-06-18T13:49:25.904+0000] {dagbag.py:545} INFO - Filling up the DagBag from /opt/airflow/dags/first_python_dag.py
[2024-06-18T13:49:25.906+0000] {logging_mixin.py:188} INFO - [2024-06-18T13:49:25.905+0000] {dagbag.py:355} ERROR - Failed to import: /opt/airflow/dags/first_python_dag.py
Traceback (most recent call last):
  File "/home/airflow/.local/lib/python3.12/site-packages/airflow/models/dagbag.py", line 351, in parse
    loader.exec_module(new_module)
  File "<frozen importlib._bootstrap_external>", line 991, in exec_module
  File "<frozen importlib._bootstrap_external>", line 1129, in get_code
  File "<frozen importlib._bootstrap_external>", line 1059, in source_to_code
  File "<frozen importlib._bootstrap>", line 488, in _call_with_frames_removed
  File "/opt/airflow/dags/first_python_dag.py", line 16
    )
    ^
SyntaxError: positional argument follows keyword argument
[2024-06-18T13:49:25.907+0000] {processor.py:842} WARNING - No viable dags retrieved from /opt/airflow/dags/first_python_dag.py
[2024-06-18T13:49:25.917+0000] {processor.py:183} INFO - Processing /opt/airflow/dags/first_python_dag.py took 0.021 seconds
[2024-06-18T13:49:56.130+0000] {processor.py:161} INFO - Started process (PID=5196) to work on /opt/airflow/dags/first_python_dag.py
[2024-06-18T13:49:56.130+0000] {processor.py:830} INFO - Processing file /opt/airflow/dags/first_python_dag.py for tasks to queue
[2024-06-18T13:49:56.131+0000] {logging_mixin.py:188} INFO - [2024-06-18T13:49:56.131+0000] {dagbag.py:545} INFO - Filling up the DagBag from /opt/airflow/dags/first_python_dag.py
[2024-06-18T13:49:56.133+0000] {logging_mixin.py:188} INFO - [2024-06-18T13:49:56.132+0000] {dagbag.py:355} ERROR - Failed to import: /opt/airflow/dags/first_python_dag.py
Traceback (most recent call last):
  File "/home/airflow/.local/lib/python3.12/site-packages/airflow/models/dagbag.py", line 351, in parse
    loader.exec_module(new_module)
  File "<frozen importlib._bootstrap_external>", line 991, in exec_module
  File "<frozen importlib._bootstrap_external>", line 1129, in get_code
  File "<frozen importlib._bootstrap_external>", line 1059, in source_to_code
  File "<frozen importlib._bootstrap>", line 488, in _call_with_frames_removed
  File "/opt/airflow/dags/first_python_dag.py", line 16
    )
    ^
SyntaxError: positional argument follows keyword argument
[2024-06-18T13:49:56.133+0000] {processor.py:842} WARNING - No viable dags retrieved from /opt/airflow/dags/first_python_dag.py
[2024-06-18T13:49:56.143+0000] {processor.py:183} INFO - Processing /opt/airflow/dags/first_python_dag.py took 0.019 seconds
[2024-06-18T13:50:26.357+0000] {processor.py:161} INFO - Started process (PID=5212) to work on /opt/airflow/dags/first_python_dag.py
[2024-06-18T13:50:26.357+0000] {processor.py:830} INFO - Processing file /opt/airflow/dags/first_python_dag.py for tasks to queue
[2024-06-18T13:50:26.358+0000] {logging_mixin.py:188} INFO - [2024-06-18T13:50:26.358+0000] {dagbag.py:545} INFO - Filling up the DagBag from /opt/airflow/dags/first_python_dag.py
[2024-06-18T13:50:26.359+0000] {logging_mixin.py:188} INFO - [2024-06-18T13:50:26.359+0000] {dagbag.py:355} ERROR - Failed to import: /opt/airflow/dags/first_python_dag.py
Traceback (most recent call last):
  File "/home/airflow/.local/lib/python3.12/site-packages/airflow/models/dagbag.py", line 351, in parse
    loader.exec_module(new_module)
  File "<frozen importlib._bootstrap_external>", line 991, in exec_module
  File "<frozen importlib._bootstrap_external>", line 1129, in get_code
  File "<frozen importlib._bootstrap_external>", line 1059, in source_to_code
  File "<frozen importlib._bootstrap>", line 488, in _call_with_frames_removed
  File "/opt/airflow/dags/first_python_dag.py", line 16
    )
    ^
SyntaxError: positional argument follows keyword argument
[2024-06-18T13:50:26.360+0000] {processor.py:842} WARNING - No viable dags retrieved from /opt/airflow/dags/first_python_dag.py
[2024-06-18T13:50:26.370+0000] {processor.py:183} INFO - Processing /opt/airflow/dags/first_python_dag.py took 0.017 seconds
[2024-06-18T13:50:56.571+0000] {processor.py:161} INFO - Started process (PID=5228) to work on /opt/airflow/dags/first_python_dag.py
[2024-06-18T13:50:56.572+0000] {processor.py:830} INFO - Processing file /opt/airflow/dags/first_python_dag.py for tasks to queue
[2024-06-18T13:50:56.572+0000] {logging_mixin.py:188} INFO - [2024-06-18T13:50:56.572+0000] {dagbag.py:545} INFO - Filling up the DagBag from /opt/airflow/dags/first_python_dag.py
[2024-06-18T13:50:56.574+0000] {logging_mixin.py:188} INFO - [2024-06-18T13:50:56.573+0000] {dagbag.py:355} ERROR - Failed to import: /opt/airflow/dags/first_python_dag.py
Traceback (most recent call last):
  File "/home/airflow/.local/lib/python3.12/site-packages/airflow/models/dagbag.py", line 351, in parse
    loader.exec_module(new_module)
  File "<frozen importlib._bootstrap_external>", line 991, in exec_module
  File "<frozen importlib._bootstrap_external>", line 1129, in get_code
  File "<frozen importlib._bootstrap_external>", line 1059, in source_to_code
  File "<frozen importlib._bootstrap>", line 488, in _call_with_frames_removed
  File "/opt/airflow/dags/first_python_dag.py", line 16
    )
    ^
SyntaxError: positional argument follows keyword argument
[2024-06-18T13:50:56.574+0000] {processor.py:842} WARNING - No viable dags retrieved from /opt/airflow/dags/first_python_dag.py
[2024-06-18T13:50:56.585+0000] {processor.py:183} INFO - Processing /opt/airflow/dags/first_python_dag.py took 0.019 seconds
[2024-06-18T13:51:26.780+0000] {processor.py:161} INFO - Started process (PID=5244) to work on /opt/airflow/dags/first_python_dag.py
[2024-06-18T13:51:26.781+0000] {processor.py:830} INFO - Processing file /opt/airflow/dags/first_python_dag.py for tasks to queue
[2024-06-18T13:51:26.781+0000] {logging_mixin.py:188} INFO - [2024-06-18T13:51:26.781+0000] {dagbag.py:545} INFO - Filling up the DagBag from /opt/airflow/dags/first_python_dag.py
[2024-06-18T13:51:26.783+0000] {logging_mixin.py:188} INFO - [2024-06-18T13:51:26.782+0000] {dagbag.py:355} ERROR - Failed to import: /opt/airflow/dags/first_python_dag.py
Traceback (most recent call last):
  File "/home/airflow/.local/lib/python3.12/site-packages/airflow/models/dagbag.py", line 351, in parse
    loader.exec_module(new_module)
  File "<frozen importlib._bootstrap_external>", line 991, in exec_module
  File "<frozen importlib._bootstrap_external>", line 1129, in get_code
  File "<frozen importlib._bootstrap_external>", line 1059, in source_to_code
  File "<frozen importlib._bootstrap>", line 488, in _call_with_frames_removed
  File "/opt/airflow/dags/first_python_dag.py", line 16
    )
    ^
SyntaxError: positional argument follows keyword argument
[2024-06-18T13:51:26.783+0000] {processor.py:842} WARNING - No viable dags retrieved from /opt/airflow/dags/first_python_dag.py
[2024-06-18T13:51:26.794+0000] {processor.py:183} INFO - Processing /opt/airflow/dags/first_python_dag.py took 0.020 seconds
[2024-06-18T13:51:56.983+0000] {processor.py:161} INFO - Started process (PID=5260) to work on /opt/airflow/dags/first_python_dag.py
[2024-06-18T13:51:56.985+0000] {processor.py:830} INFO - Processing file /opt/airflow/dags/first_python_dag.py for tasks to queue
[2024-06-18T13:51:56.986+0000] {logging_mixin.py:188} INFO - [2024-06-18T13:51:56.985+0000] {dagbag.py:545} INFO - Filling up the DagBag from /opt/airflow/dags/first_python_dag.py
[2024-06-18T13:51:56.987+0000] {logging_mixin.py:188} INFO - [2024-06-18T13:51:56.987+0000] {dagbag.py:355} ERROR - Failed to import: /opt/airflow/dags/first_python_dag.py
Traceback (most recent call last):
  File "/home/airflow/.local/lib/python3.12/site-packages/airflow/models/dagbag.py", line 351, in parse
    loader.exec_module(new_module)
  File "<frozen importlib._bootstrap_external>", line 991, in exec_module
  File "<frozen importlib._bootstrap_external>", line 1129, in get_code
  File "<frozen importlib._bootstrap_external>", line 1059, in source_to_code
  File "<frozen importlib._bootstrap>", line 488, in _call_with_frames_removed
  File "/opt/airflow/dags/first_python_dag.py", line 16
    )
    ^
SyntaxError: positional argument follows keyword argument
[2024-06-18T13:51:56.988+0000] {processor.py:842} WARNING - No viable dags retrieved from /opt/airflow/dags/first_python_dag.py
[2024-06-18T13:51:56.999+0000] {processor.py:183} INFO - Processing /opt/airflow/dags/first_python_dag.py took 0.019 seconds
[2024-06-18T13:52:27.231+0000] {processor.py:161} INFO - Started process (PID=5276) to work on /opt/airflow/dags/first_python_dag.py
[2024-06-18T13:52:27.231+0000] {processor.py:830} INFO - Processing file /opt/airflow/dags/first_python_dag.py for tasks to queue
[2024-06-18T13:52:27.232+0000] {logging_mixin.py:188} INFO - [2024-06-18T13:52:27.232+0000] {dagbag.py:545} INFO - Filling up the DagBag from /opt/airflow/dags/first_python_dag.py
[2024-06-18T13:52:27.234+0000] {logging_mixin.py:188} INFO - [2024-06-18T13:52:27.233+0000] {dagbag.py:355} ERROR - Failed to import: /opt/airflow/dags/first_python_dag.py
Traceback (most recent call last):
  File "/home/airflow/.local/lib/python3.12/site-packages/airflow/models/dagbag.py", line 351, in parse
    loader.exec_module(new_module)
  File "<frozen importlib._bootstrap_external>", line 991, in exec_module
  File "<frozen importlib._bootstrap_external>", line 1129, in get_code
  File "<frozen importlib._bootstrap_external>", line 1059, in source_to_code
  File "<frozen importlib._bootstrap>", line 488, in _call_with_frames_removed
  File "/opt/airflow/dags/first_python_dag.py", line 16
    )
    ^
SyntaxError: positional argument follows keyword argument
[2024-06-18T13:52:27.234+0000] {processor.py:842} WARNING - No viable dags retrieved from /opt/airflow/dags/first_python_dag.py
[2024-06-18T13:52:27.247+0000] {processor.py:183} INFO - Processing /opt/airflow/dags/first_python_dag.py took 0.020 seconds
